Workbook
Name Slicer_Month: #N/A

Sheet Total Sales IN&OUT
A3: Row Labels | B3: Sum of Total Out | C3: Sum of Total In
A4: January | B4: 446079 | C4: 412373
A5: February | B5: 332508 | C5: 236379
A6: March | B6: 360443 | C6: 318990
A7: April | B7: 375008 | C7: 381785
A8: May | B8: 423435 | C8: 428246
A9: June | B9: 318771 | C9: 321615
A10: July | B10: 418398 | C10: 414018
A11: August | B11: 532619 | C11: 485693
A12: September | B12: 352770 | C12: 277023
A13: October | B13: 363747 | C13: 382945
A14: November | B14: 241060 | C14: 219514
A15: December | B15: 301689 | C15: 256450
A16: Grand Total | B16: 4466527 | C16: 4135031

Sheet Summary
B4: Total | C4: January | D4: February | E4: March | F4: April | G4: May | H4: June | I4: July | J4: August | K4: September | L4: October | M4: November | N4: December
A5: Monthy Expenses | B5: =SUM(C5:Z5) -> 4466527 | C5: =January!B35 -> 446079 | D5: =Febraury!B35 -> 332508 | E5: =March!B35 -> 360443 | F5: =April!B35 -> 375008 | G5: =May!B35 -> 423435 | H5: =June!B35 -> 318771 | I5: =July!B35 -> 418398 | J5: =August!B35 -> 532619 | K5: =September!B35 -> 352770 | L5: =October!B35 -> 363747 | M5: =November!B35 -> 241060 | N5: =December!B35 -> 301689
A6: Monthly UPI | B6: =SUM(C6:Z6) -> 1719147 | C6: =January!B36 -> 202711 | D6: =Febraury!B36 -> 103017 | E6: =March!B36 -> 161780 | F6: =April!B36 -> 179193 | G6: =May!B36 -> 198977 | H6: =June!B36 -> 138259 | I6: =July!B36 -> 137405 | J6: =August!B36 -> 136248 | K6: =September!B36 -> 125267 | L6: =October!B36 -> 143462 | M6: =November!B36 -> 89420 | N6: =December!B36 -> 103408
A7: Monthly Cash | B7: =SUM(C7:Z7) -> 1695744 | C7: =January!B37 -> 172325 | D7: =Febraury!B37 -> 107353 | E7: =March!B37 -> 130212 | F7: =April!B37 -> 174719 | G7: =May!B37 -> 192297 | H7: =June!B37 -> 158111 | I7: =July!B37 -> 139836 | J7: =August!B37 -> 139181 | K7: =September!B37 -> 102373 | L7: =October!B37 -> 193388 | M7: =November!B37 -> 86502 | N7: =December!B37 -> 99447
A8: Monthly Sales | B8: =SUM(C8:Z8) -> 3414891 | C8: =January!B38 -> 375036 | D8: =Febraury!B38 -> 210370 | E8: =March!B38 -> 291992 | F8: =April!B38 -> 353912 | G8: =May!B38 -> 391274 | H8: =June!B38 -> 296370 | I8: =July!B38 -> 277241 | J8: =August!B38 -> 275429 | K8: =September!B38 -> 227640 | L8: =October!B38 -> 336850 | M8: =November!B38 -> 175922 | N8: =December!B38 -> 202855
A9: Rent, Salaries & others | B9: =SUM(C9:Z9) -> 1095294 | C9: =January!B39 -> 88972 | D9: =Febraury!B39 -> 90891 | E9: =March!B39 -> 94022 | F9: =April!B39 -> 90016 | G9: =May!B39 -> 98102 | H9: =June!B39 -> 95741 | I9: =July!B39 -> 104969 | J9: =August!B39 -> 105619 | K9: =September!B39 -> 96955 | L9: =October!B39 -> 90824 | M9: =November!B39 -> 71556 | N9: =December!B39 -> 67627
A10: Swiggy | B10: =SUM(C10:Z10) -> 516662 | C10: =January!B40 -> 23670 | D10: =Febraury!B40 -> 13455 | E10: =March!B40 -> 14648 | F10: =April!B40 -> 12085 | G10: =May!B40 -> 13612 | H10: =June!B40 -> 15441 | I10: =July!B40 -> 119593 | J10: =August!B40 -> 190054 | K10: =September!B40 -> 33874 | L10: =October!B40 -> 28853 | M10: =November!B40 -> 22814 | N10: =December!B40 -> 28563
A11: Zomato | B11: =SUM(C11:Z11) -> 203478 | C11: =January!B41 -> 13667 | D11: =Febraury!B41 -> 12554 | E11: =March!B41 -> 12350 | F11: =April!B41 -> 15788 | G11: =May!B41 -> 23360 | H11: =June!B41 -> 9804 | I11: =July!B41 -> 17184 | J11: =August!B41 -> 20210 | K11: =September!B41 -> 15509 | L11: =October!B41 -> 17242 | M11: =November!B41 -> 20778 | N11: =December!B41 -> 25032
A12: Stock | B12: =SUM(C12:Z12) -> 909295 | C12: =January!B42 -> 95268 | D12: =Febraury!B42 -> 67553 | E12: =March!B42 -> 54083 | F12: =Stock!R72 -> 70682 | G12: =May!B42 -> 95827 | H12: =June!B42 -> 54328 | I12: =July!B42 -> 85485 | J12: =August!B42 -> 127049 | K12: =September!B42 -> 81167 | L12: =October!B42 -> 90599 | M12: =November!B42 -> 27074 | N12: =December!B42 -> 60180
A13: Actual P/L | B13: =SUM(C13:Z13) -> -331496 | C13: =C8-C5+C10+C11 -> -33706 | D13: =D8-D5+D10+D11 -> -96129 | E13: =E8-E5+E10+E11 -> -41453 | F13: =F8-F5+F10+F11 -> 6777 | G13: =G8-G5+G10+G11 -> 4811 | H13: =H8-H5+H10+H11 -> 2844 | I13: =I8-I5+I10+I11 -> -4380 | J13: =J8-J5+J10+J11 -> -46926 | ... N13: =N8-N5+N10+N11 -> -45239
A15: Total In | B15: =SUM(C15:Z15) -> 4135031 | C15: =C8+C10+C11 -> 412373 | D15: =D8+D10+D11 -> 236379 | E15: =E8+E10+E11 -> 318990 | F15: =F8+F10+F11 -> 381785 | G15: =G8+G10+G11 -> 428246 | H15: =H8+H10+H11 -> 321615 | I15: =I8+I10+I11 -> 414018 | J15: =J8+J10+J11 -> 485693 | ... N15: =N8+N10+N11 -> 256450
A16: Total Out | B16: =SUM(C16:Z16) -> 4466527 | C16: =C5 -> 446079 | D16: =D5 -> 332508 | E16: =E5 -> 360443 | F16: =F5 -> 375008 | G16: =G5 -> 423435 | H16: =H5 -> 318771 | I16: =I5 -> 418398 | J16: =J5 -> 532619 | ... N16: =N5 -> 301689

Sheet Expenses
B2: Expenses - Monthly | E2: January | F2: Febraury | G2: March | H2: April | I2: May | J2: June | K2: July | L2: August | M2: September | N2: October | O2: November | P2: December
B3: Base Cost | C3: =SUM(C4:C11) -> 49700
B4: Rent | C4: 27500 | E4: 20000 | F4: 27500 | G4: 27500 | H4: 27500 | I4: 27500 | J4: 27500 | K4: 27500 | L4: 27500 | M4: 27500 | N4: 27500 | O4: 27500 | P4: 27500
B5: Maintenance | C5: 0 | E5: 0 | F5: 0 | G5: 0 | H5: 0 | I5: 0 | J5: 0 | K5: 0 | L5: 0 | M5: 0 | N5: 0 | O5: 0 | P5: 0
B6: Electricity | C6: 13000 | E6: 11662 | F6: 9296 | G6: 11001 | H6: 11516 | I6: 12288 | J6: 11469 | K6: 12218 | L6: 12590 | M6: 11419 | N6: 10050 | O6: 8949 | P6: 7207
B7: Room Rent | C7: 6000 | E7: 6000 | F7: 6000 | G7: 6000 | H7: 6000 | I7: 6000 | J7: 6000 | K7: 6000 | L7: 6000 | M7: 6000 | N7: 6000 | O7: 6000 | P7: 6000
B8: Staff - electricity | C8: 900 | E8: 730 | F8: 910 | G8: 1060 | H8: 900 | I8: 798 | J8: 642 | K8: 741 | L8: 603 | M8: 636 | N8: 474 | O8: 323 | P8: 314
B9: Wifi | C9: 500 | E9: 0 | F9: 0 | G9: 0 | H9: 0 | I9: 3000 | J9: 0 | K9: 0 | L9: 0 | M9: 0 | N9: 0 | O9: 0 | P9: 0
B10: Software | C10: 500 | E10: 0 | F10: 0 | G10: 0 | H10: 0 | I10: 0 | J10: 0 | K10: 0 | L10: 4500 | M10: 0 | N10: 0 | O10: 0 | P10: 0
B11: Pest Control | C11: 1300 | E11: 1300 | F11: 1300 | G11: 1300 | H11: 1300 | I11: 0 | J11: 1300 | K11: 0 | L11: 1300 | M11: 1200 | N11: 1300 | O11: 1300 | P11: 1800
B12: Marketing Cost | C12: 0 | E12: 0 | F12: 0 | G12: 0 | H12: 800 | I12: 0 | J12: 0 | K12: 0 | L12: 0 | M12: 0 | N12: 0 | O12: 0 | P12: 600
B13: Salaries | C13: =SUM(C14:C18) -> 56000
B14: Manager 1 | C14: 20000 | E14: 20000 | F14: 19285 | G14: 20000 | H14: 14000 | I14: 20000 | J14: 20000 | K14: 20000 | L14: 20000 | M14: 20000 | N14: 20000 | O14: 0 | P14: 0
B15: Waiter 1 | C15: 13000 | E15: 12180 | F15: 11600 | G15: 12161 | H15: 13000 | I15: 14516 | J15: 13500 | K15: 14510 | L15: 11026 | M15: 5200 | N15: 11500 | O15: 13000 | P15: 13000
B16: Waiter 2 | C16: 8000 | E16: 0 | F16: 0 | G16: 0 | H16: 0 | I16: 0 | J16: 2930 | K16: 8000 | L16: 8400 | M16: 11500 | N16: 4645 | O16: 0 | P16: 0
B17: Cleaning 1 | C17: 10000 | E17: 10000 | F17: 10000 | G17: 10000 | H17: 10000 | I17: 9000 | J17: 10000 | K17: 10000 | L17: 9670 | M17: 13000 | N17: 7420 | O17: 12330 | P17: 10000
B18: Cleaning 2 | C18: 5000 | E18: 7100 | F18: 5000 | G18: 5000 | H18: 5000 | I18: 5000 | J18: 2400 | K18: 6000 | L18: 4030 | M18: 500 | N18: 1935 | O18: =3360-1206 -> 2154 | P18: 1206
B20: Total | C20: =C3+C13 -> 105700 | E20: =SUM(E4:E18) -> 88972 | F20: =SUM(F4:F18) -> 90891 | G20: =SUM(G4:G18) -> 94022 | H20: =SUM(H4:H18) -> 90016 | I20: =SUM(I4:I18) -> 98102 | J20: =SUM(J4:J18) -> 95741 | K20: =SUM(K4:K18) -> 104969 | L20: =SUM(L4:L18) -> 105619 | ... P20: =SUM(P4:P18) -> 67627
B22: Per day | C22: =C20/30 -> 3523.3333
B24: Advance Paid to
B25: Mandi Prasad | C25: 12000
B26: Nagender Reddy | C26: 60000
B27: Nagaraju | C27: 8000
B28: Munna | C28: 0
B29: Mandi Master | C29: 0
B30: Susheela | C30: 0
B31: Munni | C31: 0
B32: Cold drinks deposit | C32: 2000
B33: Total | C33: =SUM(C25:C29) -> 80000
G37: Old | H37: New | I37: difference
F38: 45323 | G38: 550 | H38: 357 | I38: =G38-H38 -> 193
F39: 45352 | G39: 713 | H39: 463 | I39: =G39-H39 -> 250
F40: 45383 | G40: 780 | H40: =G40*0.65 -> 507 | I40: =G40-H40 -> 273
F41: 45413 | G41: 851 | H41: 553 | I41: =G41-H41 -> 298
F42: 45444 | G42: 780 | H42: =G42*0.65 -> 507 | I42: =G42-H42 -> 273
F43: 45474 | G43: 900 | H43: =G43*0.65 -> 585 | I43: =G43-H43 -> 315
F44: 45505 | G44: 924 | H44: 600 | I44: =G44-H44 -> 324
F45: 45536 | G45: 882 | H45: 573 | I45: =G45-H45 -> 309
F46: 45566 | G46: 767 | H46: 983 | I46: =G46-H46 -> -216
F47: 45597 | G47: 708 | H47: 437 | I47: =G47-H47 -> 271
...

Sheet Stock
B2: January | G2: Febraury | L2: March | Q2: April | V2: May | AA2: June | AF2: July | AK2: August | AP2: September | AU2: October | AZ2: November | BE2: December
A3: Item | B3: Quantity | C3: Price | D3: Unit Price | E3: Balance | G3: Quantity | H3: Price | I3: Unit Price | J3: Balance | L3: Quantity | M3: Price | N3: Unit Price | O3: Balance | Q3: Quantity | R3: Price | S3: Unit Price | T3: Balance | V3: Quantity | W3: Price | X3: Unit Price | Y3: Balance | AA3: Quantity | AB3: Price | AC3: Unit Price | AD3: Balance | AF3: Quantity | AG3: Price | AH3: Unit Price | AI3: Balance | AK3: Quantity | AL3: Price | AM3: Unit Price | AN3: Balance | AP3: Quantity | AQ3: Price | AR3: Unit Price | AS3: Balance | AU3: Quantity | AV3: Price | AW3: Unit Price | AX3: Balance | AZ3: Quantity | BA3: Price | BB3: Unit Price | BC3: Balance | BE3: Quantity | BF3: Price | BG3: Unit Price | BH3: Balance
A4: Sauces
A5: Green Chilli Sauce | B5: 8 | C5: 288 | D5: =IFERROR(C5/B5,0) -> 36 | E5: 1 | G5: 10 | H5: 360 | I5: =IFERROR(H5/G5,0) -> 36 | J5: 3 | L5: 8 | M5: 288 | N5: =IFERROR(M5/L5,0) -> 36 | O5: 0 | Q5: 10 | R5: 360 | S5: =IFERROR(R5/Q5,0) -> 36 | T5: 0 | V5: 13 | W5: 468 | X5: =IFERROR(W5/V5,0) -> 36 | Y5: 1 | AA5: 12 | AB5: 432 | AC5: =IFERROR(AB5/AA5,0) -> 36 | AD5: 2 | AF5: 10 | AG5: 370 | AH5: =IFERROR(AG5/AF5,0) -> 37 | AI5: 2 | AK5: 12 | AL5: 444 | AM5: =IFERROR(AL5/AK5,0) -> 37 | AN5: 1 | AP5: 12 | AQ5: 444 | AR5: =IFERROR(AQ5/AP5,0) -> 37 | AS5: 4 | AU5: 8 | AV5: 296 | AW5: =IFERROR(AV5/AU5,0) -> 37 | AX5: 1 | AZ5: 12 | BA5: 444 | BB5: =IFERROR(BA5/AZ5,0) -> 37 | BC5: 1 | BE5: 11 | BF5: 407 | BG5: =IFERROR(BF5/BE5,0) -> 37 | BH5: 1
A6: Red Chilli Sauce | B6: 5 | C6: 200 | D6: =IFERROR(C6/B6,0) -> 40 | E6: 1 | G6: 12 | H6: 480 | I6: =IFERROR(H6/G6,0) -> 40 | J6: 5 | L6: 5 | M6: 200 | N6: =IFERROR(M6/L6,0) -> 40 | O6: 0 | Q6: 7 | R6: 280 | S6: =IFERROR(R6/Q6,0) -> 40 | T6: 1 | V6: 10 | W6: 400 | X6: =IFERROR(W6/V6,0) -> 40 | Y6: 1 | AA6: 10 | AB6: 400 | AC6: =IFERROR(AB6/AA6,0) -> 40 | AD6: 5 | AF6: 6 | AG6: 240 | AH6: =IFERROR(AG6/AF6,0) -> 40 | AI6: 3 | AK6: 8 | AL6: 320 | AM6: =IFERROR(AL6/AK6,0) -> 40 | AN6: 3 | AP6: 8 | AQ6: 320 | AR6: =IFERROR(AQ6/AP6,0) -> 40 | AS6: 6 | AU6: 6 | AV6: 240 | AW6: =IFERROR(AV6/AU6,0) -> 40 | AX6: 6 | AZ6: 6 | BA6: 240 | BB6: =IFERROR(BA6/AZ6,0) -> 40 | BC6: 10 | BE6: 2 | BF6: 80 | BG6: =IFERROR(BF6/BE6,0) -> 40 | BH6: 12
A7: Capsicum Sauce | B7: 0 | C7: 0 | D7: =IFERROR(C7/B7,0) -> 0 | E7: 2 | G7: 8 | H7: 320 | I7: =IFERROR(H7/G7,0) -> 40 | J7: 4 | L7: 4 | M7: 160 | N7: =IFERROR(M7/L7,0) -> 40 | O7: 0 | Q7: 8 | R7: 320 | S7: =IFERROR(R7/Q7,0) -> 40 | T7: 2 | V7: 10 | W7: 400 | X7: =IFERROR(W7/V7,0) -> 40 | Y7: 6 | AA7: 6 | AB7: 240 | AC7: =IFERROR(AB7/AA7,0) -> 40 | AD7: 6 | AF7: 6 | AG7: =AC7*AF7 -> 240 | AH7: =IFERROR(AG7/AF7,0) -> 40 | AI7: 6 | AK7: 6 | AL7: 240 | AM7: =IFERROR(AL7/AK7,0) -> 40 | AN7: 6 | AP7: 6 | AQ7: 240 | AR7: =IFERROR(AQ7/AP7,0) -> 40 | AS7: 5 | AU7: 7 | AV7: 280 | AW7: =IFERROR(AV7/AU7,0) -> 40 | AX7: 10 | AZ7: 0 | BA7: 0 | BB7: =IFERROR(BA7/AZ7,0) -> 0 | BC7: 6 | BE7: 4 | BF7: 160 | BG7: =IFERROR(BF7/BE7,0) -> 40 | BH7: 4
A8: Tomato Sauce | B8: 6 | C8: 480 | D8: =IFERROR(C8/B8,0) -> 80 | E8: 1 | G8: 12 | H8: 900 | I8: =IFERROR(H8/G8,0) -> 75 | J8: 8 | L8: 0 | M8: 0 | N8: =IFERROR(M8/L8,0) -> 0 | O8: 0 | Q8: 10 | R8: 800 | S8: =IFERROR(R8/Q8,0) -> 80 | T8: 1 | V8: 12 | W8: 960 | X8: =IFERROR(W8/V8,0) -> 80 | Y8: 2 | AA8: 9 | AB8: 720 | AC8: =IFERROR(AB8/AA8,0) -> 80 | AD8: 3 | AF8: 8 | AG8: =AC8*AF8 -> 640 | AH8: =IFERROR(AG8/AF8,0) -> 80 | AI8: 2 | AK8: 9 | AL8: 720 | AM8: =IFERROR(AL8/AK8,0) -> 80 | AN8: 2 | AP8: 9 | AQ8: 810 | AR8: =IFERROR(AQ8/AP8,0) -> 90 | AS8: 6 | AU8: 6 | AV8: 480 | AW8: =IFERROR(AV8/AU8,0) -> 80 | AX8: 1 | AZ8: 12 | BA8: 900 | BB8: =IFERROR(BA8/AZ8,0) -> 75 | BC8: 5 | BE8: 8 | BF8: 640 | BG8: =IFERROR(BF8/BE8,0) -> 80 | BH8: 4
A9: 8to8 Sauce | B9: 2 | C9: 110 | D9: =IFERROR(C9/B9,0) -> 55 | E9: 1 | G9: 5 | H9: 275 | I9: =IFERROR(H9/G9,0) -> 55 | J9: 2 | L9: 3 | M9: 165 | N9: =IFERROR(M9/L9,0) -> 55 | O9: 0 | Q9: 4 | R9: 220 | S9: =IFERROR(R9/Q9,0) -> 55 | T9: 0 | V9: 5 | W9: 275 | X9: =IFERROR(W9/V9,0) -> 55 | Y9: 1 | AA9: 4 | AB9: 220 | AC9: =IFERROR(AB9/AA9,0) -> 55 | AD9: 2 | AF9: 3 | AG9: =AC9*AF9 -> 165 | AH9: =IFERROR(AG9/AF9,0) -> 55 | AI9: 3 | AK9: 2 | AL9: 110 | AM9: =IFERROR(AL9/AK9,0) -> 55 | AN9: 4 | AP9: 1 | AQ9: 55 | AR9: =IFERROR(AQ9/AP9,0) -> 55 | AS9: 2 | AU9: 3 | AV9: 165 | AW9: =IFERROR(AV9/AU9,0) -> 55 | AX9: 0 | AZ9: 5 | BA9: 275 | BB9: =IFERROR(BA9/AZ9,0) -> 55 | BC9: 3 | BE9: 2 | BF9: 110 | BG9: =IFERROR(BF9/BE9,0) -> 55 | BH9: 2
A10: Soya Sauce | B10: 0 | C10: 0 | D10: =IFERROR(C10/B10,0) -> 0 | E10: 6 | G10: 0 | H10: 0 | I10: =IFERROR(H10/G10,0) -> 0 | J10: 4 | L10: 0 | M10: 0 | N10: =IFERROR(M10/L10,0) -> 0 | O10: 0 | Q10: 3 | R10: 114 | S10: =IFERROR(R10/Q10,0) -> 38 | T10: 1 | V10: 4 | W10: 152 | X10: =IFERROR(W10/V10,0) -> 38 | Y10: 2 | AA10: 3 | AB10: 120 | AC10: =IFERROR(AB10/AA10,0) -> 40 | AD10: 4 | AF10: 1 | AG10: 38 | AH10: =IFERROR(AG10/AF10,0) -> 38 | AI10: 3 | AK10: 2 | AL10: 76 | AM10: =IFERROR(AL10/AK10,0) -> 38 | AN10: 3 | AP10: 2 | AQ10: 76 | AR10: =IFERROR(AQ10/AP10,0) -> 38 | AS10: 4 | AU10: 2 | AV10: 76 | AW10: =IFERROR(AV10/AU10,0) -> 38 | AX10: 5 | AZ10: 0 | BA10: 0 | BB10: =IFERROR(BA10/AZ10,0) -> 0 | BC10: 3 | BE10: 2 | BF10: 76 | BG10: =IFERROR(BF10/BE10,0) -> 38 | BH10: 4
A11: Vinegar | B11: 0 | C11: 0 | D11: =IFERROR(C11/B11,0) -> 0 | E11: 3 | G11: 3 | H11: 75 | I11: =IFERROR(H11/G11,0) -> 25 | J11: 2 | L11: 3 | M11: 75 | N11: =IFERROR(M11/L11,0) -> 25 | O11: 0 | Q11: 3 | R11: 75 | S11: =IFERROR(R11/Q11,0) -> 25 | T11: 2 | V11: 6 | W11: 150 | X11: =IFERROR(W11/V11,0) -> 25 | Y11: 2 | AA11: 6 | AB11: 90 | AC11: =IFERROR(AB11/AA11,0) -> 15 | AD11: 6 | AF11: 2 | AG11: 50 | AH11: =IFERROR(AG11/AF11,0) -> 25 | AI11: 8 | AK11: 0 | AL11: 0 | AM11: =IFERROR(AL11/AK11,0) -> 0 | AN11: 6 | AP11: 0 | AQ11: 0 | AR11: =IFERROR(AQ11/AP11,0) -> 0 | AS11: 5 | AU11: 0 | AV11: 0 | AW11: =IFERROR(AV11/AU11,0) -> 0 | AX11: 3 | AZ11: 0 | BA11: 0 | BB11: =IFERROR(BA11/AZ11,0) -> 0 | BC11: 4 | BE11: 0 | BF11: 0 | BG11: =IFERROR(BF11/BE11,0) -> 0 | BH11: 2
A12: Schezwan Sauce | B12: 2 | C12: 180 | D12: =IFERROR(C12/B12,0) -> 90 | E12: 2 | G12: 2 | H12: 180 | I12: =IFERROR(H12/G12,0) -> 90 | J12: 1 | L12: 3 | M12: 270 | N12: =IFERROR(M12/L12,0) -> 90 | O12: 0 | Q12: 3 | R12: 270 | S12: =IFERROR(R12/Q12,0) -> 90 | T12: 1 | V12: 4 | W12: 360 | X12: =IFERROR(W12/V12,0) -> 90 | Y12: 1 | AA12: 4 | AB12: 360 | AC12: =IFERROR(AB12/AA12,0) -> 90 | AD12: 2 | AF12: 3 | AG12: =AC12*AF12 -> 270 | AH12: =IFERROR(AG12/AF12,0) -> 90 | AI12: 2 | AK12: 3 | AL12: 270 | AM12: =IFERROR(AL12/AK12,0) -> 90 | AN12: 1 | AP12: 4 | AQ12: 150 | AR12: =IFERROR(AQ12/AP12,0) -> 37.5 | AS12: 0 | AU12: 5 | AV12: 450 | AW12: =IFERROR(AV12/AU12,0) -> 90 | AX12: 1 | AZ12: 5 | BA12: 750 | BB12: =IFERROR(BA12/AZ12,0) -> 150 | BC12: 3 | BE12: 0 | BF12: 0 | BG12: =IFERROR(BF12/BE12,0) -> 0 | BH12: 2
A13: Rose Water | B13: 1 | C13: 70 | D13: =IFERROR(C13/B13,0) -> 70 | E13: 1 | G13: 2 | H13: 140 | I13: =IFERROR(H13/G13,0) -> 70 | J13: 0 | L13: 3 | M13: 210 | N13: =IFERROR(M13/L13,0) -> 70 | O13: 0 | Q13: 2 | R13: 140 | S13: =IFERROR(R13/Q13,0) -> 70 | T13: 2 | V13: 1 | W13: 70 | X13: =IFERROR(W13/V13,0) -> 70 | Y13: 0 | AA13: 3 | AB13: 210 | AC13: =IFERROR(AB13/AA13,0) -> 70 | AD13: 1 | AF13: 5 | AG13: =AC13*AF13 -> 350 | AH13: =IFERROR(AG13/AF13,0) -> 70 | AI13: 0 | AK13: 9 | AL13: 630 | AM13: =IFERROR(AL13/AK13,0) -> 70 | AN13: 3 | AP13: 3 | AQ13: 210 | AR13: =IFERROR(AQ13/AP13,0) -> 70 | AS13: 4 | AU13: 10 | AV13: 700 | AW13: =IFERROR(AV13/AU13,0) -> 70 | AX13: 3 | AZ13: 6 | BA13: 420 | BB13: =IFERROR(BA13/AZ13,0) -> 70 | BC13: 4 | BE13: 5 | BF13: 350 | BG13: =IFERROR(BF13/BE13,0) -> 70 | BH13: 3
A14: Kewada water | B14: 1 | C14: 70 | D14: =IFERROR(C14/B14,0) -> 70 | E14: 1 | G14: 2 | H14: 140 | I14: =IFERROR(H14/G14,0) -> 70 | J14: 1 | L14: 2 | M14: 140 | N14: =IFERROR(M14/L14,0) -> 70 | O14: 0 | Q14: 2 | R14: 140 | S14: =IFERROR(R14/Q14,0) -> 70 | T14: 1 | V14: 2 | W14: 140 | X14: =IFERROR(W14/V14,0) -> 70 | Y14: 0 | AA14: 3 | AB14: 210 | AC14: =IFERROR(AB14/AA14,0) -> 70 | AD14: 0 | AF14: 6 | AG14: =AC14*AF14 -> 420 | AH14: =IFERROR(AG14/AF14,0) -> 70 | AI14: 0 | AK14: 9 | AL14: 630 | AM14: =IFERROR(AL14/AK14,0) -> 70 | AN14: 3 | AP14: 3 | AQ14: 210 | AR14: =IFERROR(AQ14/AP14,0) -> 70 | AS14: 4 | AU14: 10 | AV14: 700 | AW14: =IFERROR(AV14/AU14,0) -> 70 | AX14: 3 | AZ14: 6 | BA14: 420 | BB14: =IFERROR(BA14/AZ14,0) -> 70 | BC14: 4 | BE14: 5 | BF14: 350 | BG14: =IFERROR(BF14/BE14,0) -> 70 | BH14: 3
A15: Garam Masala (kg) | B15: 0 | C15: 0 | D15: =IFERROR(C15/B15,0) -> 0 | E15: 2 | G15: 1 | H15: 250 | I15: =IFERROR(H15/G15,0) -> 250 | J15: 2 | L15: 0 | M15: 0 | N15: =IFERROR(M15/L15,0) -> 0 | O15: 0 | Q15: 1 | R15: 250 | S15: =IFERROR(R15/Q15,0) -> 250 | T15: 1 | V15: 1 | W15: 250 | X15: =IFERROR(W15/V15,0) -> 250 | Y15: 0 | AA15: 2 | AB15: 500 | AC15: =IFERROR(AB15/AA15,0) -> 250 | AD15: 1 | AF15: 1 | AG15: =AC15*AF15 -> 250 | AH15: =IFERROR(AG15/AF15,0) -> 250 | AI15: 0 | AK15: 3 | AL15: 780 | AM15: =IFERROR(AL15/AK15,0) -> 260 | AN15: 1 | AP15: 2 | AQ15: 500 | AR15: =IFERROR(AQ15/AP15,0) -> 250 | AS15: 4.4 | AU15: 0 | AV15: 0 | AW15: =IFERROR(AV15/AU15,0) -> 0 | AX15: 2 | AZ15: 0 | BA15: 0 | BB15: =IFERROR(BA15/AZ15,0) -> 0 | BC15: 2 | BE15: 0 | BF15: 0 | BG15: =IFERROR(BF15/BE15,0) -> 0 | BH15: 1
A16: White pepper (kg) | B16: 1 | C16: 130 | D16: =IFERROR(C16/B16,0) -> 130 | E16: 1.5 | G16: 1.5 | H16: 105 | I16: =IFERROR(H16/G16,0) -> 70 | J16: 2 | L16: 0 | M16: 0 | N16: =IFERROR(M16/L16,0) -> 0 | O16: 0 | Q16: 3 | R16: 390 | S16: =IFERROR(R16/Q16,0) -> 130 | T16: 0.5 | V16: 2.5 | W16: 325 | X16: =IFERROR(W16/V16,0) -> 130 | Y16: 0.5 | AA16: 3 | AB16: 210 | AC16: =IFERROR(AB16/AA16,0) -> 70 | AD16: 1 | AF16: 2.5 | AG16: 325 | AH16: =IFERROR(AG16/AF16,0) -> 130 | AI16: 1 | AK16: 2.5 | AL16: 325 | AM16: =IFERROR(AL16/AK16,0) -> 130 | AN16: 1 | AP16: 2.5 | AQ16: 325 | AR16: =IFERROR(AQ16/AP16,0) -> 130 | AS16: 2 | AU16: 2 | AV16: 260 | AW16: =IFERROR(AV16/AU16,0) -> 130 | AX16: 0.5 | AZ16: 3 | BA16: 210 | BB16: =IFERROR(BA16/AZ16,0) -> 70 | BC16: 2 | BE16: 2 | BF16: 140 | BG16: =IFERROR(BF16/BE16,0) -> 70 | BH16: 0.5
A17: Chicken Masala (kg) | B17: 2 | C17: 1300 | D17: =IFERROR(C17/B17,0) -> 650 | E17: 0.4 | G17: 3 | H17: 1950 | I17: =IFERROR(H17/G17,0) -> 650 | J17: 2 | L17: 1 | M17: 630 | N17: =IFERROR(M17/L17,0) -> 630 | O17: 0 | Q17: 2 | R17: 1260 | S17: =IFERROR(R17/Q17,0) -> 630 | T17: 1 | V17: 3 | W17: 1890 | X17: =IFERROR(W17/V17,0) -> 630 | Y17: 0 | AA17: 3 | AB17: 1950 | AC17: =IFERROR(AB17/AA17,0) -> 650 | AD17: 1 | AF17: 3 | AG17: =AC17*AF17 -> 1950 | AH17: =IFERROR(AG17/AF17,0) -> 650 | AI17: 0.5 | AK17: =6+1 -> 7 | AL17: =3900+300 -> 4200 | AM17: =IFERROR(AL17/AK17,0) -> 600 | AN17: 2 | AP17: 0 | AQ17: 0 | AR17: =IFERROR(AQ17/AP17,0) -> 0 | AS17: 1 | AU17: 2 | AV17: 1300 | AW17: =IFERROR(AV17/AU17,0) -> 650 | AX17: 0 | AZ17: 3 | BA17: 1950 | BB17: =IFERROR(BA17/AZ17,0) -> 650 | BC17: 1 | BE17: 2 | BF17: 1300 | BG17: =IFERROR(BF17/BE17,0) -> 650 | BH17: 0
A18: Mutton Masala (kg) | B18: 1 | C18: 650 | D18: =IFERROR(C18/B18,0) -> 650 | E18: 2 | G18: 1 | H18: 650 | I18: =IFERROR(H18/G18,0) -> 650 | J18: 2 | L18: 0 | M18: 0 | N18: =IFERROR(M18/L18,0) -> 0 | O18: 0 | Q18: 1 | R18: 630 | S18: =IFERROR(R18/Q18,0) -> 630 | T18: 0 | V18: 2 | W18: 1260 | X18: =IFERROR(W18/V18,0) -> 630 | Y18: 0 | AA18: 2 | AB18: 1300 | AC18: =IFERROR(AB18/AA18,0) -> 650 | AD18: 0 | AF18: 3 | AG18: =AC18*AF18 -> 1950 | AH18: =IFERROR(AG18/AF18,0) -> 650 | AI18: 0 | AK18: 4 | AL18: 2520 | AM18: =IFERROR(AL18/AK18,0) -> 630 | AN18: 2 | AP18: 0 | AQ18: 0 | AR18: =IFERROR(AQ18/AP18,0) -> 0 | AS18: 0 | AU18: 2 | AV18: 1300 | AW18: =IFERROR(AV18/AU18,0) -> 650 | AX18: 0 | AZ18: 3 | BA18: 1950 | BB18: =IFERROR(BA18/AZ18,0) -> 650 | BC18: 1 | BE18: 2 | BF18: 1300 | BG18: =IFERROR(BF18/BE18,0) -> 650 | BH18: 1
A19: Tandoori Chicken Masala (kg) | B19: 0 | C19: 0 | D19: =IFERROR(C19/B19,0) -> 0 | E19: 1 | G19: 0 | H19: 0 | I19: =IFERROR(H19/G19,0) -> 0 | J19: 0 | L19: 1 | M19: 630 | N19: =IFERROR(M19/L19,0) -> 630 | O19: 0 | Q19: 0 | R19: 0 | S19: =IFERROR(R19/Q19,0) -> 0 | T19: 1 | V19: 1 | W19: 650 | X19: =IFERROR(W19/V19,0) -> 650 | Y19: 2 | AA19: 0 | AB19: 0 | AC19: =IFERROR(AB19/AA19,0) -> 0 | AD19: 1 | AF19: 1 | AG19: =650*AF19 -> 650 | AH19: =IFERROR(AG19/AF19,0) -> 650 | AI19: 2 | AK19: 1 | AL19: 650 | AM19: =IFERROR(AL19/AK19,0) -> 650 | AN19: 2 | AP19: 0 | AQ19: 0 | AR19: =IFERROR(AQ19/AP19,0) -> 0 | AS19: 3 | AU19: 0 | AV19: 0 | AW19: =IFERROR(AV19/AU19,0) -> 0 | AX19: 1 | AZ19: 0 | BA19: 0 | BB19: =IFERROR(BA19/AZ19,0) -> 0 | BC19: 2 | BE19: 0 | BF19: 0 | BG19: =IFERROR(BF19/BE19,0) -> 0 | BH19: 1
A20: Chat Masala (kg) | B20: 1 | C20: 550 | D20: =IFERROR(C20/B20,0) -> 550 | E20: 1 | G20: 2 | H20: 1100 | I20: =IFERROR(H20/G20,0) -> 550 | J20: 3 | L20: 0 | M20: 0 | N20: =IFERROR(M20/L20,0) -> 0 | O20: 0 | Q20: 3 | R20: 1650 | S20: =IFERROR(R20/Q20,0) -> 550 | T20: 2 | V20: 1 | W20: 550 | X20: =IFERROR(W20/V20,0) -> 550 | Y20: 1 | AA20: 0 | AB20: 0 | AC20: =IFERROR(AB20/AA20,0) -> 0 | AD20: 2 | AF20: 0 | AG20: =AC20*AF20 -> 0 | AH20: =IFERROR(AG20/AF20,0) -> 0 | AI20: 0 | AK20: =2+0.2 -> 2.2 | AL20: =1100+150 -> 1250 | AM20: =IFERROR(AL20/AK20,0) -> 568.18182 | AN20: 0 | AP20: 1 | AQ20: 550 | AR20: =IFERROR(AQ20/AP20,0) -> 550 | AS20: 0 | AU20: 1 | AV20: 550 | AW20: =IFERROR(AV20/AU20,0) -> 550 | AX20: 0 | AZ20: 1 | BA20: 550 | BB20: =IFERROR(BA20/AZ20,0) -> 550 | BC20: 1 | BE20: 0 | BF20: 0 | BG20: =IFERROR(BF20/BE20,0) -> 0 | BH20: 1
A21: Corn Powder (kg) | B21: 12 | C21: 588 | D21: =IFERROR(C21/B21,0) -> 49 | E21: 0 | G21: 25 | H21: 1225 | I21: =IFERROR(H21/G21,0) -> 49 | J21: 11 | L21: 15 | M21: 720 | N21: =IFERROR(M21/L21,0) -> 48 | O21: 0 | Q21: 13 | R21: 611 | S21: =IFERROR(R21/Q21,0) -> 47 | T21: 6 | V21: 20 | W21: 940 | X21: =IFERROR(W21/V21,0) -> 47 | Y21: 5 | AA21: 20 | AB21: 940 | AC21: =IFERROR(AB21/AA21,0) -> 47 | AD21: 10 | AF21: 15 | AG21: =AC21*AF21 -> 705 | AH21: =IFERROR(AG21/AF21,0) -> 47 | AI21: 8 | AK21: 17 | AL21: 799 | AM21: =IFERROR(AL21/AK21,0) -> 47 | AN21: 5 | AP21: 20 | AQ21: 920 | AR21: =IFERROR(AQ21/AP21,0) -> 46 | AS21: 13 | AU21: 15 | AV21: 690 | AW21: =IFERROR(AV21/AU21,0) -> 46 | AX21: 10 | AZ21: 15 | BA21: 675 | BB21: =IFERROR(BA21/AZ21,0) -> 45 | BC21: 10 | BE21: 15 | BF21: 645 | BG21: =IFERROR(BF21/BE21,0) -> 43 | BH21: 14
A22: Tasting salt (kg) | B22: 5 | C22: 900 | D22: =IFERROR(C22/B22,0) -> 180 | E22: 0 | G22: 6 | H22: 1020 | I22: =IFERROR(H22/G22,0) -> 170 | J22: 2 | L22: 4 | M22: 680 | N22: =IFERROR(M22/L22,0) -> 170 | O22: 0 | Q22: 5 | R22: 850 | S22: =IFERROR(R22/Q22,0) -> 170 | T22: 0 | V22: 6 | W22: 1020 | X22: =IFERROR(W22/V22,0) -> 170 | Y22: 0 | AA22: 4 | AB22: 720 | AC22: =IFERROR(AB22/AA22,0) -> 180 | AD22: 0 | AF22: 7 | AG22: =680+510 -> 1190 | AH22: =IFERROR(AG22/AF22,0) -> 170 | AI22: 0 | AK22: =10+1 -> 11 | AL22: =1700+160 -> 1860 | AM22: =IFERROR(AL22/AK22,0) -> 169.09091 | AN22: 0 | AP22: 5 | AQ22: 850 | AR22: =IFERROR(AQ22/AP22,0) -> 170 | AS22: 1 | AU22: 5 | AV22: 850 | AW22: =IFERROR(AV22/AU22,0) -> 170 | AX22: 0 | AZ22: 3 | BA22: 510 | BB22: =IFERROR(BA22/AZ22,0) -> 170 | BC22: 0 | BE22: 3 | BF22: 510 | BG22: =IFERROR(BF22/BE22,0) -> 170 | BH22: 0
A23: Red Color (box) | B23: 0 | C23: 0 | D23: =IFERROR(C23/B23,0) -> 0 | E23: 2 | G23: 6 | H23: 360 | I23: =IFERROR(H23/G23,0) -> 60 | J23: 3 | L23: 5 | M23: 300 | N23: =IFERROR(M23/L23,0) -> 60 | O23: 0 | Q23: 5 | R23: 300 | S23: =IFERROR(R23/Q23,0) -> 60 | T23: 4 | V23: 4 | W23: 240 | X23: =IFERROR(W23/V23,0) -> 60 | Y23: 3 | AA23: 5 | AB23: 300 | AC23: =IFERROR(AB23/AA23,0) -> 60 | AD23: 3 | AF23: 5 | AG23: =AC23*AF23 -> 300 | AH23: =IFERROR(AG23/AF23,0) -> 60 | AI23: 4 | AK23: 5 | AL23: 300 | AM23: =IFERROR(AL23/AK23,0) -> 60 | AN23: 3 | AP23: 7 | AQ23: 420 | AR23: =IFERROR(AQ23/AP23,0) -> 60 | AS23: 5 | AU23: 5 | AV23: 300 | AW23: =IFERROR(AV23/AU23,0) -> 60 | AX23: 4 | AZ23: 2 | BA23: 120 | BB23: =IFERROR(BA23/AZ23,0) -> 60 | BC23: 8 | BE23: 0 | BF23: 0 | BG23: =IFERROR(BF23/BE23,0) -> 0 | BH23: 5
A24: Yellow Color (box) | B24: 5 | C24: 300 | D24: =IFERROR(C24/B24,0) -> 60 | E24: 4 | G24: 2 | H24: 120 | I24: =IFERROR(H24/G24,0) -> 60 | J24: 6 | L24: 0 | M24: 0 | N24: =IFERROR(M24/L24,0) -> 0 | O24: 0 | Q24: 6 | R24: 360 | S24: =IFERROR(R24/Q24,0) -> 60 | T24: 0 | V24: 6 | W24: 360 | X24: =IFERROR(W24/V24,0) -> 60 | Y24: 3 | AA24: 3 | AB24: 180 | AC24: =IFERROR(AB24/AA24,0) -> 60 | AD24: 3 | AF24: 3 | AG24: =AC24*AF24 -> 180 | AH24: =IFERROR(AG24/AF24,0) -> 60 | AI24: 0 | AK24: 10 | AL24: 600 | AM24: =IFERROR(AL24/AK24,0) -> 60 | AN24: 3 | AP24: 7 | AQ24: 420 | AR24: =IFERROR(AQ24/AP24,0) -> 60 | AS24: 6 | AU24: 6 | AV24: 360 | AW24: =IFERROR(AV24/AU24,0) -> 60 | AX24: 4 | AZ24: 6 | BA24: 360 | BB24: =IFERROR(BA24/AZ24,0) -> 60 | BC24: 8 | BE24: 0 | BF24: 0 | BG24: =IFERROR(BF24/BE24,0) -> 0 | BH24: 1
A25: Main Items
A26: Biryani Rice (kg) | B26: =338+25+75 -> 438 | C26: =30420+400+1600+3240 -> 35660 | D26: =IFERROR(C26/B26,0) -> 81.415525 | E26: 95 | G26: =(26*6)+(3*25) -> 231 | H26: =(26*8*90) -> 18720 | I26: =IFERROR(H26/G26,0) -> 81.038961 | J26: 166 | L26: 156 | M26: =26*90*6 -> 14040 | N26: =IFERROR(M26/L26,0) -> 90 | O26: 0 | Q26: 130 | R26: =26*90*5 -> 11700 | S26: =IFERROR(R26/Q26,0) -> 90 | T26: 26 | V26: =(26*12)+25 -> 337 | W26: =(26*12*90)+1600 -> 29680 | X26: =IFERROR(W26/V26,0) -> 88.071217 | Y26: 96 | AA26: =26*6 -> 156 | AB26: =AA26*90 -> 14040 | AC26: =IFERROR(AB26/AA26,0) -> 90 | AD26: 70 | AF26: =(26*9)+(30*2) -> 294 | AG26: =AC26*AF26 -> 26460 | AH26: =IFERROR(AG26/AF26,0) -> 90 | AI26: 199 | AK26: =30*18+52 -> 592 | AL26: =540*90+2060 -> 50660 | AM26: =IFERROR(AL26/AK26,0) -> 85.574324 | AN26: 0 | AP26: =12*30 -> 360 | AQ26: =AP26*93 -> 33480 | AR26: =IFERROR(AQ26/AP26,0) -> 93 | AS26: 90 | AU26: 300 | AV26: =AU26*91+2040 -> 29340 | AW26: =IFERROR(AV26/AU26,0) -> 97.8 | AX26: 115 | AZ26: =2*30 -> 60 | BA26: =AZ26*92 -> 5520 | BB26: =IFERROR(BA26/AZ26,0) -> 92 | BC26: 0 | BE26: =6*30 -> 180 | BF26: =BE26*92 -> 16560 | BG26: =IFERROR(BF26/BE26,0) -> 92 | BH26: 0
A27: Oil (L) | B27: 150 | C27: =9200+9350 -> 18550 | D27: =IFERROR(C27/B27,0) -> 123.66667 | E27: 6 | G27: 135 | H27: 16650 | I27: =IFERROR(H27/G27,0) -> 123.33333 | J27: 38 | L27: 105 | M27: 12600 | N27: =IFERROR(M27/L27,0) -> 120 | O27: 0 | Q27: 120 | R27: =1700*8 -> 13600 | S27: =IFERROR(R27/Q27,0) -> 113.33333 | T27: 5 | V27: =150+20 -> 170 | W27: =(113*150)+2200 -> 19150 | X27: =IFERROR(W27/V27,0) -> 112.64706 | Y27: 4 | AA27: 102 | AB27: =AA27*110 -> 11220 | AC27: =IFERROR(AB27/AA27,0) -> 110 | AD27: 15 | AF27: =48+10+10+10+10+10+10+10+10+10 -> 138 | AG27: =1320+3600+1240+1240+1240+1240+1240+1270+1260+1250+1270 -> 16170 | AH27: =IFERROR(AG27/AF27,0) -> 117.17391 | AI27: 0 | AK27: 320 | AL27: =17300+18500-7400 -> 28400 | AM27: =IFERROR(AL27/AK27,0) -> 88.75 | AN27: 16 | AP27: =64+48 -> 112 | AQ27: =7400+5490 -> 12890 | AR27: =IFERROR(AQ27/AP27,0) -> 115.08929 | AS27: 18 | AU27: =20+160 -> 180 | AV27: =2980+17900 -> 20880 | AW27: =IFERROR(AV27/AU27,0) -> 116 | AX27: 45 | AZ27: =2*16 -> 32 | BA27: =AZ27*112.5 -> 3600 | BB27: =IFERROR(BA27/AZ27,0) -> 112.5 | BC27: 0 | BE27: =8*16 -> 128 | BF27: =BE27*112.5 -> 14400 | BG27: =IFERROR(BF27/BE27,0) -> 112.5 | BH27: 14
A28: Maida (kg) | B28: 30 | C28: 1985 | D28: =IFERROR(C28/B28,0) -> 66.166667 | E28: 25 | G28: 25 | H28: 1050 | I28: =IFERROR(H28/G28,0) -> 42 | J28: 22 | L28: 0 | M28: 0 | N28: =IFERROR(M28/L28,0) -> 0 | O28: 0 | Q28: 25 | R28: 1050 | S28: =IFERROR(R28/Q28,0) -> 42 | T28: 0 | V28: 25 | W28: 1050 | X28: =IFERROR(W28/V28,0) -> 42 | Y28: 0 | AA28: 25 | AB28: 1000 | AC28: =IFERROR(AB28/AA28,0) -> 40 | AD28: 0 | AF28: 25 | AG28: =AC28*AF28 -> 1000 | AH28: =IFERROR(AG28/AF28,0) -> 40 | AI28: 2 | AK28: 0 | AL28: 0 | AM28: =IFERROR(AL28/AK28,0) -> 0 | AN28: 0 | AP28: 0 | AQ28: 0 | AR28: =IFERROR(AQ28/AP28,0) -> 0 | AS28: 3 | AU28: 25 | AV28: 1000 | AW28: =IFERROR(AV28/AU28,0) -> 40 | AX28: 10 | AZ28: 15 | BA28: 660 | BB28: =IFERROR(BA28/AZ28,0) -> 44 | BC28: 7 | BE28: 10 | BF28: 400 | BG28: =IFERROR(BF28/BE28,0) -> 40 | BH28: 5
A29: Aata (kg) | B29: 15 | C29: 820 | D29: =IFERROR(C29/B29,0) -> 54.666667 | E29: 5 | G29: 15 | H29: 630 | I29: =IFERROR(H29/G29,0) -> 42 | J29: 8 | L29: 15 | M29: 615 | N29: =IFERROR(M29/L29,0) -> 41 | O29: 0 | Q29: 15 | R29: 630 | S29: =IFERROR(R29/Q29,0) -> 42 | T29: 5 | V29: 15 | W29: 585 | X29: =IFERROR(W29/V29,0) -> 39 | Y29: 8 | AA29: 20 | AB29: 760 | AC29: =IFERROR(AB29/AA29,0) -> 38 | AD29: 7 | AF29: 28 | AG29: =AC29*AF29 -> 1064 | AH29: =IFERROR(AG29/AF29,0) -> 38 | AI29: 25 | AK29: 0 | AL29: 0 | AM29: =IFERROR(AL29/AK29,0) -> 0 | AN29: 10 | AP29: 0 | AQ29: 0 | AR29: =IFERROR(AQ29/AP29,0) -> 0 | AS29: 7 | AU29: 5 | AV29: 200 | AW29: =IFERROR(AV29/AU29,0) -> 40 | AX29: 0 | AZ29: 5 | BA29: 0 | BB29: =IFERROR(BA29/AZ29,0) -> 0 | BC29: 0 | BE29: 3 | BF29: 120 | BG29: =IFERROR(BF29/BE29,0) -> 40 | BH29: 0.5
A30: Cold Drinks (cases) | B30: 15 | C30: 7275 | D30: =IFERROR(C30/B30,0) -> 485 | E30: 7 | G30: 9 | H30: 4365 | I30: =IFERROR(H30/G30,0) -> 485 | J30: 0 | L30: 8 | M30: 3880 | N30: =IFERROR(M30/L30,0) -> 485 | O30: 0 | Q30: 12 | R30: =12*485 -> 5820 | S30: =IFERROR(R30/Q30,0) -> 485 | T30: 0 | V30: 12 | W30: 5820 | X30: =IFERROR(W30/V30,0) -> 485 | Y30: 0 | AA30: 12 | AB30: 0 | AC30: =IFERROR(AB30/AA30,0) -> 0 | AD30: 0 | AF30: 12 | AG30: 5820 | AH30: =IFERROR(AG30/AF30,0) -> 485 | AI30: 0 | AK30: 0 | AL30: 0 | AM30: =IFERROR(AL30/AK30,0) -> 0 | AN30: 0 | AP30: 10 | AQ30: =AP30*486 -> 4860 | AR30: =IFERROR(AQ30/AP30,0) -> 486 | AS30: 0 | AU30: 17 | AV30: =AU30*485 -> 8245 | AW30: =IFERROR(AV30/AU30,0) -> 485 | AX30: 0 | AZ30: 0 | BA30: 0 | BB30: =IFERROR(BA30/AZ30,0) -> 0 | BC30: 0 | BE30: 0 | BF30: 0 | BG30: =IFERROR(BF30/BE30,0) -> 0 | BH30: 0
A31: Cold Drinks (bottles) | B31: 6 | C31: 1182 | D31: =IFERROR(C31/B31,0) -> 197 | E31: 1 | G31: 9 | H31: 1773 | I31: =IFERROR(H31/G31,0) -> 197 | J31: 0 | L31: 8 | M31: 1576 | N31: =IFERROR(M31/L31,0) -> 197 | O31: 0 | Q31: 12 | R31: =12*197 -> 2364 | S31: =IFERROR(R31/Q31,0) -> 197 | T31: 0 | V31: 16 | W31: 3152 | X31: =IFERROR(W31/V31,0) -> 197 | Y31: 0 | AA31: 12 | AB31: 0 | AC31: =IFERROR(AB31/AA31,0) -> 0 | AD31: 0 | AF31: 16 | AG31: 3152 | AH31: =IFERROR(AG31/AF31,0) -> 197 | AI31: 0 | AK31: 0 | AL31: 0 | AM31: =IFERROR(AL31/AK31,0) -> 0 | AN31: 0 | AP31: 14 | AQ31: =AP31*198 -> 2772 | AR31: =IFERROR(AQ31/AP31,0) -> 198 | AS31: 0 | AU31: 10 | AV31: =AU31*197 -> 1970 | AW31: =IFERROR(AV31/AU31,0) -> 197 | AX31: 0 | AZ31: 0 | BA31: 0 | BB31: =IFERROR(BA31/AZ31,0) -> 0 | BC31: 0 | BE31: 0 | BF31: 0 | BG31: =IFERROR(BF31/BE31,0) -> 0 | BH31: 0
A32: Cold Drinks (cans) | B32: 0 | C32: 0 | D32: =IFERROR(C32/B32,0) -> 0 | E32: 0 | G32: 0 | H32: 0 | I32: =IFERROR(H32/G32,0) -> 0 | J32: 0 | L32: 0 | M32: 0 | N32: =IFERROR(M32/L32,0) -> 0 | O32: 0 | Q32: 0 | R32: 0 | S32: =IFERROR(R32/Q32,0) -> 0 | T32: 0 | V32: 0 | W32: 0 | X32: =IFERROR(W32/V32,0) -> 0 | Y32: 0 | AA32: 0 | AB32: 0 | AC32: =IFERROR(AB32/AA32,0) -> 0 | AD32: 0 | AF32: 0 | AG32: 0 | AH32: =IFERROR(AG32/AF32,0) -> 0 | AI32: 0 | AK32: 0 | AL32: 0 | AM32: =IFERROR(AL32/AK32,0) -> 0 | AN32: 0 | AP32: 0 | AQ32: 0 | AR32: =IFERROR(AQ32/AP32,0) -> 0 | AS32: 0 | AU32: 0 | AV32: 0 | AW32: =IFERROR(AV32/AU32,0) -> 0 | AX32: 0 | AZ32: 0 | BA32: 0 | BB32: =IFERROR(BA32/AZ32,0) -> 0 | BC32: 0 | BE32: 0 | BF32: 0 | BG32: =IFERROR(BF32/BE32,0) -> 0 | BH32: 0
A33: Water Bottles (cases) | B33: 100 | C33: 13200 | D33: =IFERROR(C33/B33,0) -> 132 | E33: 43 | G33: 0 | H33: 0 | I33: =IFERROR(H33/G33,0) -> 0 | J33: 0 | L33: 40 | M33: =L33*132 -> 5280 | N33: =IFERROR(M33/L33,0) -> 132 | O33: 0 | Q33: 90 | R33: =Q33*132 -> 11880 | S33: =IFERROR(R33/Q33,0) -> 132 | T33: 0 | V33: 50 | W33: 6600 | X33: =IFERROR(W33/V33,0) -> 132 | Y33: 0 | AA33: 58 | AB33: =6600+960 -> 7560 | AC33: =IFERROR(AB33/AA33,0) -> 130.34483 | AD33: 0 | AF33: 59 | AG33: 7788 | AH33: =IFERROR(AG33/AF33,0) -> 132 | AI33: 0 | AK33: 50 | AL33: 6600 | AM33: =IFERROR(AL33/AK33,0) -> 132 | AN33: 0 | AP33: 50 | AQ33: 6600 | AR33: =IFERROR(AQ33/AP33,0) -> 132 | AS33: 0 | AU33: 50 | AV33: =50*132 -> 6600 | AW33: =IFERROR(AV33/AU33,0) -> 132 | AX33: 0 | AZ33: 0 | BA33: 0 | BB33: 0 | BC33: 0 | BE33: 50 | BF33: 6600 | BG33: =IFERROR(BF33/BE33,0) -> 132 | BH33: 0
A34: Alibeg
A35: Baby Kaju (kg) | B35: 2 | C35: 640 | D35: =IFERROR(C35/B35,0) -> 320 | E35: 0 | G35: 2 | H35: 600 | I35: =IFERROR(H35/G35,0) -> 300 | J35: 0 | L35: 2 | M35: 600 | N35: =IFERROR(M35/L35,0) -> 300 | O35: 0 | Q35: 2 | R35: 0 | S35: =IFERROR(R35/Q35,0) -> 0 | T35: 0 | V35: 2 | W35: 0 | X35: =IFERROR(W35/V35,0) -> 0 | Y35: 0 | AA35: 2 | AB35: 600 | AC35: =IFERROR(AB35/AA35,0) -> 300 | AD35: 0 | AF35: 2 | AG35: 620 | AH35: =IFERROR(AG35/AF35,0) -> 310 | AI35: 0 | AK35: 2 | AL35: 660 | AM35: =IFERROR(AL35/AK35,0) -> 330 | AN35: 0 | AP35: 2 | AQ35: 640 | AR35: =IFERROR(AQ35/AP35,0) -> 320 | AS35: 0 | AU35: 2 | AV35: 680 | AW35: =IFERROR(AV35/AU35,0) -> 340 | AX35: 0 | AZ35: 0 | BA35: 0 | BB35: =IFERROR(BA35/AZ35,0) -> 0 | BC35: 0 | BE35: 2 | BF35: 0 | BG35: =IFERROR(BF35/BE35,0) -> 0 | BH35: 0
A36: Kaju 4 pieces (kg) | B36: 4 | C36: 3080 | D36: =IFERROR(C36/B36,0) -> 770 | E36: 0 | G36: 7 | H36: 4970 | I36: =IFERROR(H36/G36,0) -> 710 | J36: 2 | L36: 5 | M36: 3750 | N36: =IFERROR(M36/L36,0) -> 750 | O36: 0 | Q36: 8 | R36: 5920 | S36: =IFERROR(R36/Q36,0) -> 740 | T36: 0 | V36: 10 | W36: 7500 | X36: =IFERROR(W36/V36,0) -> 750 | Y36: 0 | AA36: 6 | AB36: 4475 | AC36: =IFERROR(AB36/AA36,0) -> 745.83333 | AD36: 0.5 | AF36: 6 | AG36: 4320 | AH36: =IFERROR(AG36/AF36,0) -> 720 | AI36: 0 | AK36: =10+0.1 -> 10.1 | AL36: =7100+90 -> 7190 | AM36: =IFERROR(AL36/AK36,0) -> 711.88119 | AN36: 0 | AP36: 10 | AQ36: 7100 | AR36: =IFERROR(AQ36/AP36,0) -> 710 | AS36: 3 | AU36: 10 | AV36: 7100 | AW36: =IFERROR(AV36/AU36,0) -> 710 | AX36: 7.5 | AZ36: 2 | BA36: 0 | BB36: =IFERROR(BA36/AZ36,0) -> 0 | BC36: 0.5 | BE36: 10 | BF36: 7100 | BG36: =IFERROR(BF36/BE36,0) -> 710 | BH36: 8
A37: Haldi (kg) | B37: 0 | C37: 0 | D37: =IFERROR(C37/B37,0) -> 0 | E37: 1 | G37: 1 | H37: 250 | I37: =IFERROR(H37/G37,0) -> 250 | J37: 1.5 | L37: 0 | M37: 0 | N37: =IFERROR(M37/L37,0) -> 0 | O37: 0 | Q37: 1 | R37: 250 | S37: =IFERROR(R37/Q37,0) -> 250 | T37: 0.5 | V37: 1 | W37: 240 | X37: =IFERROR(W37/V37,0) -> 240 | Y37: 0.5 | AA37: 1 | AB37: 220 | AC37: =IFERROR(AB37/AA37,0) -> 220 | AD37: 0 | AF37: 1.5 | AG37: 360 | AH37: =IFERROR(AG37/AF37,0) -> 240 | AI37: 0 | AK37: 2 | AL37: 450 | AM37: =IFERROR(AL37/AK37,0) -> 225 | AN37: 0 | AP37: 2 | AQ37: 460 | AR37: =IFERROR(AQ37/AP37,0) -> 230 | AS37: 2 | AU37: 0 | AV37: 0 | AW37: =IFERROR(AV37/AU37,0) -> 0 | AX37: 1 | AZ37: 0 | BA37: 0 | BB37: =IFERROR(BA37/AZ37,0) -> 0 | BC37: 1 | BE37: 0 | BF37: 0 | BG37: =IFERROR(BF37/BE37,0) -> 0 | BH37: 0.5
A38: Jeera (kg) | B38: 0 | C38: 0 | D38: =IFERROR(C38/B38,0) -> 0 | E38: 0.5 | G38: 1 | H38: 330 | I38: =IFERROR(H38/G38,0) -> 330 | J38: 0.7 | L38: 1 | M38: 280 | N38: =IFERROR(M38/L38,0) -> 280 | O38: 0 | Q38: 0.2 | R38: 75 | S38: =IFERROR(R38/Q38,0) -> 375 | T38: 0 | V38: 2 | W38: 700 | X38: =IFERROR(W38/V38,0) -> 350 | Y38: 0.4 | AA38: 1 | AB38: 320 | AC38: =IFERROR(AB38/AA38,0) -> 320 | AD38: 1 | AF38: 0.5 | AG38: 180 | AH38: =IFERROR(AG38/AF38,0) -> 360 | AI38: 0.4 | AK38: 1.6 | AL38: 450 | AM38: =IFERROR(AL38/AK38,0) -> 281.25 | AN38: 0.9 | AP38: 1 | AQ38: 380 | AR38: =IFERROR(AQ38/AP38,0) -> 380 | AS38: 1 | AU38: 0 | AV38: 0 | AW38: =IFERROR(AV38/AU38,0) -> 0 | AX38: 1.1 | AZ38: 0 | BA38: 0 | BB38: =IFERROR(BA38/AZ38,0) -> 0 | BC38: 1 | BE38: 0 | BF38: 0 | BG38: =IFERROR(BF38/BE38,0) -> 0 | BH38: 0.9
A39: Til (kg) | B39: 1 | C39: 190 | D39: =IFERROR(C39/B39,0) -> 190 | E39: 0 | G39: 1 | H39: 250 | I39: =IFERROR(H39/G39,0) -> 250 | J39: 0 | L39: 1 | M39: 280 | N39: =IFERROR(M39/L39,0) -> 280 | O39: 0 | Q39: 1 | R39: 240 | S39: =IFERROR(R39/Q39,0) -> 240 | T39: 0 | V39: 1 | W39: 210 | X39: =IFERROR(W39/V39,0) -> 210 | Y39: 0 | AA39: 1 | AB39: 200 | AC39: =IFERROR(AB39/AA39,0) -> 200 | AD39: 0 | AF39: =1+1 -> 2 | AG39: =230+180 -> 410 | AH39: =IFERROR(AG39/AF39,0) -> 205 | AI39: 0 | AK39: 1 | AL39: 225 | AM39: =IFERROR(AL39/AK39,0) -> 225 | AN39: 0 | AP39: 1 | AQ39: 200 | AR39: =IFERROR(AQ39/AP39,0) -> 200 | AS39: 0 | AU39: 1 | AV39: 220 | AW39: =IFERROR(AV39/AU39,0) -> 220 | AX39: 0 | AZ39: 1 | BA39: 230 | BB39: =IFERROR(BA39/AZ39,0) -> 230 | BC39: 0 | BE39: 1 | BF39: 200 | BG39: =IFERROR(BF39/BE39,0) -> 200 | BH39: 0
A40: Charmagash (kg) | B40: 1 | C40: 650 | D40: =IFERROR(C40/B40,0) -> 650 | E40: 0 | G40: 1 | H40: 630 | I40: =IFERROR(H40/G40,0) -> 630 | J40: 0 | L40: 1 | M40: 630 | N40: =IFERROR(M40/L40,0) -> 630 | O40: 0 | Q40: 1 | R40: 630 | S40: =IFERROR(R40/Q40,0) -> 630 | T40: 0 | V40: 1 | W40: 660 | X40: =IFERROR(W40/V40,0) -> 660 | Y40: 0 | AA40: 1 | AB40: 770 | AC40: =IFERROR(AB40/AA40,0) -> 770 | AD40: 0 | AF40: =1+1 -> 2 | AG40: =760+662 -> 1422 | AH40: =IFERROR(AG40/AF40,0) -> 711 | AI40: 0 | AK40: 1 | AL40: 760 | AM40: =IFERROR(AL40/AK40,0) -> 760 | AN40: 0 | AP40: 1 | AQ40: 750 | AR40: =IFERROR(AQ40/AP40,0) -> 750 | AS40: 0 | AU40: 1 | AV40: 790 | AW40: =IFERROR(AV40/AU40,0) -> 790 | AX40: 0 | AZ40: 1 | BA40: 680 | BB40: =IFERROR(BA40/AZ40,0) -> 680 | BC40: 0 | BE40: 1 | BF40: 750 | BG40: =IFERROR(BF40/BE40,0) -> 750 | BH40: 0
A41: Kash Kash (kg) | B41: 0 | C41: 0 | D41: =IFERROR(C41/B41,0) -> 0 | E41: 0 | G41: 0.1 | H41: 130 | I41: =IFERROR(H41/G41,0) -> 1300 | J41: 0 | L41: 0.1 | M41: 130 | N41: =IFERROR(M41/L41,0) -> 1300 | O41: 0 | Q41: 0.1 | R41: 150 | S41: =IFERROR(R41/Q41,0) -> 1500 | T41: 0 | V41: 0.1 | W41: 145 | X41: =IFERROR(W41/V41,0) -> 1450 | Y41: 0 | AA41: 0.1 | AB41: 160 | AC41: =IFERROR(AB41/AA41,0) -> 1600 | AD41: 0 | AF41: =0.1+0.2 -> 0.3 | AG41: =190+360 -> 550 | AH41: =IFERROR(AG41/AF41,0) -> 1833.3333 | AI41: 0 | AK41: 0.1 | AL41: 220 | AM41: =IFERROR(AL41/AK41,0) -> 2200 | AN41: 0 | AP41: 0.1 | AQ41: 200 | AR41: =IFERROR(AQ41/AP41,0) -> 2000 | AS41: 0 | AU41: 0.1 | AV41: 160 | AW41: =IFERROR(AV41/AU41,0) -> 1600 | AX41: 0 | AZ41: 0.1 | BA41: 200 | BB41: =IFERROR(BA41/AZ41,0) -> 2000 | BC41: 0 | BE41: 0.1 | BF41: 165 | BG41: =IFERROR(BF41/BE41,0) -> 1650 | BH41: 0
...

Sheet Clean_Data
A1: Month | B1: Item Name | C1: Quantity
A3: January | B3: Green Chilli Sauce | C3: 8
A4: January | B4: Red Chilli Sauce | C4: 5
A5: January | B5: Capsicum Sauce | C5: 0
A6: January | B6: Tomato Sauce | C6: 6
A7: January | B7: 8to8 Sauce | C7: 2
A8: January | B8: Soya Sauce | C8: 0
A9: January | B9: Vinegar | C9: 0
A10: January | B10: Schezwan Sauce | C10: 2
A11: January | B11: Rose Water | C11: 1
A12: January | B12: Kewada water | C12: 1
A13: January | B13: Garam Masala (kg) | C13: 0
A14: January | B14: White pepper (kg) | C14: 1
... A757: December | B757: Boxes | C757: 0
A758: January | C758: Balance
A759: January | B759: Green Chilli Sauce | C759: 1
A760: January | B760: Red Chilli Sauce | C760: 1
A761: January | B761: Capsicum Sauce | C761: 2
A762: January | B762: Tomato Sauce | C762: 1
A763: January | B763: 8to8 Sauce | C763: 1
A764: January | B764: Soya Sauce | C764: 6
A765: January | B765: Vinegar | C765: 3
A766: January | B766: Schezwan Sauce | C766: 2
A767: January | B767: Rose Water | C767: 1
A768: January | B768: Kewada water | C768: 1
A769: January | B769: Garam Masala (kg) | C769: 2
A770: January | B770: White pepper (kg) | C770: 1.5
... A820: January | B820: Boxes | C820: 0
A821: Febraury | C821: Balance
A822: Febraury | B822: Green Chilli Sauce | C822: 3
A823: Febraury | B823: Red Chilli Sauce | C823: 5
A824: Febraury | B824: Capsicum Sauce | C824: 4
A825: Febraury | B825: Tomato Sauce | C825: 8
A826: Febraury | B826: 8to8 Sauce | C826: 2
A827: Febraury | B827: Soya Sauce | C827: 4
A828: Febraury | B828: Vinegar | C828: 2
A829: Febraury | B829: Schezwan Sauce | C829: 1
A830: Febraury | B830: Rose Water | C830: 0
A831: Febraury | B831: Kewada water | C831: 1
A832: Febraury | B832: Garam Masala (kg) | C832: 2
...

Sheet Stock Analysis
A1: Month+ | B1: Month | D1: Green Chilli Sauce | E1: Red Chilli Sauce | F1: Capsicum Sauce | G1: Tomato Sauce | H1: 8to8 Sauce | I1: Soya Sauce | J1: Vinegar | K1: Schezwan Sauce | L1: Rose Water | M1: Kewada water | N1: Garam Masala (kg) | O1: White pepper (kg) | P1: Chicken Masala (kg) | Q1: Mutton Masala (kg) | R1: Tandoori Chicken Masala (kg) | S1: Chat Masala (kg) | T1: Corn Powder (kg) | U1: Tasting salt (kg) | V1: Red Color (box) | W1: Yellow Color (box) | X1: Biryani Rice (kg) | Y1: Oil (L) | Z1: Maida (kg) | AA1: Aata (kg) | AB1: Cold Drinks (cases) | AC1: Cold Drinks (bottles) | AD1: Cold Drinks (cans) | AE1: Water Bottles (cases) | AF1: Baby Kaju (kg) | AG1: Kaju 4 pieces (kg) | AH1: Haldi (kg) | AI1: Jeera (kg) | AJ1: Til (kg) | AK1: Charmagash (kg) | AL1: Kash Kash (kg) | AM1: Salt (kg) | AN1: Big salt (kg) | AO1: Elaichi (kg) | AP1: Loung (kg) | AQ1: Dalchini (kg) | AR1: Star Phool (kg) | AS1: Jai Phool (kg) | AT1: Shazira (kg) | AU1: Biryani patta (kg) | AV1: Kastur methi (kg) | AW1: Japhal (kg) | AX1: Japatri | AY1: Kabab Chini | AZ1: Kali Mirch/Miryalu | BA1: Big Elaichi | BB1: Phatar ka Phool (kg) | BC1: Gulab Ka phool | BD1: Bread Crumbs (kg) | BE1: Kismis | BF1: Maggi Cube | BG1: Dhaniya (kg) | BH1: Sugar (kg) | BI1: Dalda (kg) | BJ1: Red Chilli Powder (kg) | BK1: Dhaniya Powder (kg) | BL1: Coal (bags) | BM1: Boxes
A2: January(Quantity) | B2: January | C2: Quantity | D2: 8 | E2: 5 | F2: 0 | G2: 6 | H2: 2 | I2: 0 | J2: 0 | K2: 2 | L2: 1 | M2: 1 | N2: 0 | O2: 1 | P2: 2 | Q2: 1 | R2: 0 | S2: 1 | T2: 12 | U2: 5 | V2: 0 | W2: 5 | X2: 438 | Y2: 150 | Z2: 30 | AA2: 15 | AB2: 15 | AC2: 6 | AD2: 0 | AE2: 100 | AF2: 2 | AG2: 4 | AH2: 0 | AI2: 0 | AJ2: 1 | AK2: 1 | AL2: 0 | AM2: 10 | AN2: 10 | AO2: 0.4 | AP2: 0.5 | AQ2: 0 | AR2: 0 | AS2: 0 | AT2: 0 | AU2: 0 | AV2: 0.5 | AW2: 0 | AX2: 0 | AY2: 0 | AZ2: 0 | BA2: 0 | BB2: 0 | BC2: 0 | BD2: 1 | BE2: 3 | BF2: 24 | BG2: 0.5 | BH2: 5 | BI2: 1 | BJ2: 0 | BK2: 0 | BL2: 0 | BM2: 400
A3: Febraury(Quantity) | B3: Febraury | C3: Quantity | D3: 10 | E3: 12 | F3: 8 | G3: 12 | H3: 5 | I3: 0 | J3: 3 | K3: 2 | L3: 2 | M3: 2 | N3: 1 | O3: 1.5 | P3: 3 | Q3: 1 | R3: 0 | S3: 2 | T3: 25 | U3: 6 | V3: 6 | W3: 2 | X3: 231 | Y3: 135 | Z3: 25 | AA3: 15 | AB3: 9 | AC3: 9 | AD3: 0 | AE3: 0 | AF3: 2 | AG3: 7 | AH3: 1 | AI3: 1 | AJ3: 1 | AK3: 1 | AL3: 0.1 | AM3: 25 | AN3: 25 | AO3: 0.5 | AP3: 0.5 | AQ3: 0.5 | AR3: 1 | AS3: 0 | AT3: 0.5 | AU3: 0.3 | AV3: 0.5 | AW3: 0 | AX3: 0.5 | AY3: 0 | AZ3: 0 | BA3: 0 | BB3: 0 | BC3: 0 | BD3: 2 | BE3: 2 | BF3: 24 | BG3: 2 | BH3: 5 | BI3: 1 | BJ3: 0 | BK3: 0 | BL3: 1 | BM3: 0
A4: March(Quantity) | B4: March | C4: Quantity | D4: 8 | E4: 5 | F4: 4 | G4: 0 | H4: 3 | I4: 0 | J4: 3 | K4: 3 | L4: 3 | M4: 2 | N4: 0 | O4: 0 | P4: 1 | Q4: 0 | R4: 1 | S4: 0 | T4: 15 | U4: 4 | V4: 5 | W4: 0 | X4: 156 | Y4: 105 | Z4: 0 | AA4: 15 | AB4: 8 | AC4: 8 | AD4: 0 | AE4: 40 | AF4: 2 | AG4: 5 | AH4: 0 | AI4: 1 | AJ4: 1 | AK4: 1 | AL4: 0.1 | AM4: 0 | AN4: 15 | AO4: 0.5 | AP4: 0.3 | AQ4: 0 | AR4: 0 | AS4: 0 | AT4: 0.3 | AU4: 0 | AV4: 0 | AW4: 0 | AX4: 0 | AY4: 0 | AZ4: 0 | BA4: 0 | BB4: 0 | BC4: 0 | BD4: 0 | BE4: 2 | BF4: 0 | BG4: 0 | BH4: 3 | BI4: 1 | BJ4: 0 | BK4: 2 | BL4: 1 | BM4: 400
A5: April(Quantity) | B5: April | C5: Quantity | D5: 10 | E5: 7 | F5: 8 | G5: 10 | H5: 4 | I5: 3 | J5: 3 | K5: 3 | L5: 2 | M5: 2 | N5: 1 | O5: 3 | P5: 2 | Q5: 1 | R5: 0 | S5: 3 | T5: 13 | U5: 5 | V5: 5 | W5: 6 | X5: 130 | Y5: 120 | Z5: 25 | AA5: 15 | AB5: 12 | AC5: 12 | AD5: 0 | AE5: 90 | AF5: 2 | AG5: 8 | AH5: 1 | AI5: 0.2 | AJ5: 1 | AK5: 1 | AL5: 0.1 | AM5: 10 | AN5: 17 | AO5: 0.6 | AP5: 0.2 | AQ5: 0.5 | AR5: 0.3 | AS5: 0 | AT5: 0.6 | AU5: 0 | AV5: 1 | AW5: 0 | AX5: 0.3 | AY5: 0 | AZ5: 0 | BA5: 0 | BB5: 0 | BC5: 0 | BD5: 1 | BE5: 1.5 | BF5: 14 | BG5: 0 | BH5: 5 | BI5: 1 | BJ5: 0 | BK5: 2 | BL5: 0 | BM5: 400
A6: May(Quantity) | B6: May | C6: Quantity | D6: 13 | E6: 10 | F6: 10 | G6: 12 | H6: 5 | I6: 4 | J6: 6 | K6: 4 | L6: 1 | M6: 2 | N6: 1 | O6: 2.5 | P6: 3 | Q6: 2 | R6: 1 | S6: 1 | T6: 20 | U6: 6 | V6: 4 | W6: 6 | X6: 337 | Y6: 170 | Z6: 25 | AA6: 15 | AB6: 12 | AC6: 16 | AD6: 0 | AE6: 50 | AF6: 2 | AG6: 10 | AH6: 1 | AI6: 2 | AJ6: 1 | AK6: 1 | AL6: 0.1 | AM6: 12 | AN6: 15 | AO6: 1 | AP6: 0 | AQ6: 1 | AR6: 0.4 | AS6: 0 | AT6: 0.7 | AU6: 0.2 | AV6: 1 | AW6: 0 | AX6: 0.2 | AY6: 0 | AZ6: 1 | BA6: 0.4 | BB6: 0.1 | BC6: 0 | BD6: 1 | BE6: 1.5 | BF6: 24 | BG6: 0.5 | BH6: 5 | BI6: 1 | BJ6: 0 | BK6: 2 | BL6: 0 | BM6: 0
A7: June(Quantity) | B7: June | C7: Quantity | D7: 12 | E7: 10 | F7: 6 | G7: 9 | H7: 4 | I7: 3 | J7: 6 | K7: 4 | L7: 3 | M7: 3 | N7: 2 | O7: 3 | P7: 3 | Q7: 2 | R7: 0 | S7: 0 | T7: 20 | U7: 4 | V7: 5 | W7: 3 | X7: 156 | Y7: 102 | Z7: 25 | AA7: 20 | AB7: 12 | AC7: 12 | AD7: 0 | AE7: 58 | AF7: 2 | AG7: 6 | AH7: 1 | AI7: 1 | AJ7: 1 | AK7: 1 | AL7: 0.1 | AM7: 13 | AN7: 10 | AO7: 0.4 | AP7: 0 | AQ7: 1 | AR7: 0 | AS7: 0 | AT7: 1 | AU7: 0 | AV7: 0 | AW7: 0 | AX7: 0.3 | AY7: 0 | AZ7: 0 | BA7: 0 | BB7: 0 | BC7: 0 | BD7: 0 | BE7: 0 | BF7: 0 | BG7: 0 | BH7: 4 | BI7: 1 | BJ7: 0 | BK7: 2 | BL7: 1 | BM7: 0
A8: July(Quantity) | B8: July | C8: Quantity | D8: 10 | E8: 6 | F8: 6 | G8: 8 | H8: 3 | I8: 1 | J8: 2 | K8: 3 | L8: 5 | M8: 6 | N8: 1 | O8: 2.5 | P8: 3 | Q8: 3 | R8: 1 | S8: 0 | T8: 15 | U8: 7 | V8: 5 | W8: 3 | X8: 294 | Y8: 138 | Z8: 25 | AA8: 28 | AB8: 12 | AC8: 16 | AD8: 0 | AE8: 59 | AF8: 2 | AG8: 6 | AH8: 1.5 | AI8: 0.5 | AJ8: 2 | AK8: 2 | AL8: 0.3 | AM8: 10 | AN8: 22 | AO8: 0.5 | AP8: 0.5 | AQ8: 0.6 | AR8: 0.3 | AS8: 0 | AT8: 1 | AU8: 0.2 | AV8: 0 | AW8: 0 | AX8: 0.6 | AY8: 0 | AZ8: 0 | BA8: 0 | BB8: 0 | BC8: 0 | BD8: 0 | BE8: 0 | BF8: 0 | BG8: 0 | BH8: 4 | BI8: 2 | BJ8: 0 | BK8: 3 | BL8: 0 | BM8: 0
A9: August (Quantity) | B9: August | C9: Quantity | D9: 12 | E9: 8 | F9: 6 | G9: 9 | H9: 2 | I9: 2 | J9: 0 | K9: 3 | L9: 9 | M9: 9 | N9: 3 | O9: 2.5 | P9: 7 | Q9: 4 | R9: 1 | S9: 2.2 | T9: 17 | U9: 11 | V9: 5 | W9: 10 | X9: 592 | Y9: 320 | Z9: 0 | AA9: 0 | AB9: 0 | AC9: 0 | AD9: 0 | AE9: 50 | AF9: 2 | AG9: 10.1 | AH9: 2 | AI9: 1.6 | AJ9: 1 | AK9: 1 | AL9: 0.1 | AM9: 15 | AN9: 30 | AO9: 1.5 | AP9: 0.5 | AQ9: 1 | AR9: 1 | AS9: 0 | AT9: 0.5 | AU9: 0.5 | AV9: 3 | AW9: 0 | AX9: 1.2 | AY9: 0 | AZ9: 0.5 | BA9: 0 | BB9: 0 | BC9: 0 | BD9: 2 | BE9: 2 | BF9: 24 | BG9: 0.5 | BH9: 5 | BI9: 1 | BJ9: 1 | BK9: 3 | BL9: 1 | BM9: 200
A10: September(Quantity) | B10: September | C10: Quantity | D10: 12 | E10: 8 | F10: 6 | G10: 9 | H10: 1 | I10: 2 | J10: 0 | K10: 4 | L10: 3 | M10: 3 | N10: 2 | O10: 2.5 | P10: 0 | Q10: 0 | R10: 0 | S10: 1 | T10: 20 | U10: 5 | V10: 7 | W10: 7 | X10: 360 | Y10: 112 | Z10: 0 | AA10: 0 | AB10: 10 | AC10: 14 | AD10: 0 | AE10: 50 | AF10: 2 | AG10: 10 | AH10: 2 | AI10: 1 | AJ10: 1 | AK10: 1 | AL10: 0.1 | AM10: 15 | AN10: 30 | AO10: 0 | AP10: 0 | AQ10: 0.5 | AR10: 0.5 | AS10: 0 | AT10: 1 | AU10: 0 | AV10: 0 | AW10: 0 | AX10: 1 | AY10: 0 | AZ10: 0 | BA10: 0 | BB10: 0 | BC10: 0 | BD10: 0 | BE10: 0 | BF10: 0 | BG10: 0 | BH10: 3 | BI10: 1 | BJ10: 0 | BK10: 3 | BL10: 1 | BM10: 0
A11: October(Quantity) | B11: October | C11: Quantity | D11: 8 | E11: 6 | F11: 7 | G11: 6 | H11: 3 | I11: 2 | J11: 0 | K11: 5 | L11: 10 | M11: 10 | N11: 0 | O11: 2 | P11: 2 | Q11: 2 | R11: 0 | S11: 1 | T11: 15 | U11: 5 | V11: 5 | W11: 6 | X11: 300 | Y11: 180 | Z11: 25 | AA11: 5 | AB11: 17 | AC11: 10 | AD11: 0 | AE11: 50 | AF11: 2 | AG11: 10 | AH11: 0 | AI11: 0 | AJ11: 1 | AK11: 1 | AL11: 0.1 | AM11: 0 | AN11: 15 | AO11: 0.5 | AP11: 0 | AQ11: 0 | AR11: 0.4 | AS11: 0 | AT11: 1 | AU11: 0 | AV11: 0 | AW11: 0 | AX11: 0 | AY11: 0 | AZ11: 0 | BA11: 0 | BB11: 0 | BC11: 0 | BD11: 0 | BE11: 0 | BF11: 0 | BG11: 0 | BH11: 0 | BI11: 0 | BJ11: 0 | BK11: 3 | BL11: 0 | BM11: 600
A12: November(Quantity) | B12: November | C12: Quantity | D12: 12 | E12: 6 | F12: 0 | G12: 12 | H12: 5 | I12: 0 | J12: 0 | K12: 5 | L12: 6 | M12: 6 | N12: 0 | O12: 3 | P12: 3 | Q12: 3 | R12: 0 | S12: 1 | T12: 15 | U12: 3 | V12: 2 | W12: 6 | X12: 60 | Y12: 32 | Z12: 15 | AA12: 5 | AB12: 0 | AC12: 0 | AD12: 0 | AE12: 0 | AF12: 0 | AG12: 2 | AH12: 0 | AI12: 0 | AJ12: 1 | AK12: 1 | AL12: 0.1 | AM12: 10 | AN12: 15 | AO12: 0.5 | AP12: 0 | AQ12: 0.5 | AR12: 0 | AS12: 0 | AT12: 0.5 | AU12: 0 | AV12: 0 | AW12: 0 | AX12: 0 | AY12: 0 | AZ12: 0 | BA12: 0 | BB12: 0 | BC12: 0 | BD12: 0 | BE12: 0 | BF12: 0 | BG12: 0 | BH12: 2 | BI12: 1 | BJ12: 0 | BK12: 2 | BL12: 0 | BM12: 600
A13: December(Quantity) | B13: December | C13: Quantity | D13: 11 | E13: 2 | F13: 4 | G13: 8 | H13: 2 | I13: 2 | J13: 0 | K13: 0 | L13: 5 | M13: 5 | N13: 0 | O13: 2 | P13: 2 | Q13: 2 | R13: 0 | S13: 0 | T13: 15 | U13: 3 | V13: 0 | W13: 0 | X13: 180 | Y13: 128 | Z13: 10 | AA13: 3 | AB13: 0 | AC13: 0 | AD13: 0 | AE13: 50 | AF13: 2 | AG13: 10 | AH13: 0 | AI13: 0 | AJ13: 1 | AK13: 1 | AL13: 0.1 | AM13: 8 | AN13: 15 | AO13: 0.5 | AP13: 0.25 | AQ13: 0.5 | AR13: 0.2 | AS13: 0 | AT13: 1 | AU13: 0.2 | AV13: 0 | AW13: 0 | AX13: 0.3 | AY13: 0 | AZ13: 0 | BA13: 0 | BB13: 0 | BC13: 0 | BD13: 0 | BE13: 0 | BF13: 0 | BG13: 0 | BH13: 3 | BI13: 1 | BJ13: 0 | BK13: 2 | BL13: 0 | BM13: 0
... A49: December(Unit Price) | B49: December | C49: Unit Price | D49: 37 | E49: 40 | F49: 40 | G49: 80 | H49: 55 | I49: 38 | J49: 0 | K49: 0 | L49: 70 | M49: 70 | N49: 0 | O49: 70 | P49: 650 | Q49: 650 | R49: 0 | S49: 0 | T49: 43 | U49: 170 | V49: 0 | W49: 0 | X49: 92 | Y49: 112.5 | Z49: 40 | AA49: 40 | AB49: 0 | AC49: 0 | AD49: 0 | AE49: 132 | AF49: 0 | AG49: 710 | AH49: 0 | AI49: 0 | AJ49: 200 | AK49: 750 | AL49: 1650 | AM49: 14 | AN49: 14 | AO49: 3400 | AP49: 1000 | AQ49: 400 | AR49: 750 | AS49: 0 | AT49: 330 | AU49: 2000 | AV49: 0 | AW49: 0 | AX49: 2600 | AY49: 0 | AZ49: 0 | BA49: 0 | BB49: 0 | BC49: 0 | BD49: 0 | BE49: 0 | BF49: 0 | BG49: 0 | BH49: 45 | BI49: 330 | BJ49: 0 | BK49: 70 | BL49: 0 | BM49: 0

Sheet Inventory
B1: Biryani | F1: Mandi | J1: Chicken Bodies (KG) | N1: Chicken Lollipop | R1: Chicken Boneless | V1: Pet Bottles | Z1: Glass Bottles | AE1: Water Bottles
A2: Column1 | B2: Cooked KG | C2: Plates Sold | D2: Plates Left | E2: Column2 | F2: Cooked KG3 | G2: Plates Sold4 | H2: Plates Left5 | I2: Column6 | J2: Ordered | K2: Used | L2: Left | M2: Column7 | N2: Ordered KG | O2: Plates Sold8 | P2: Left KG | Q2: Column9 | R2: Ordered KG10 | S2: Plates Sold11 | T2: Left KG12 | U2: Column13 | V2: Thumbsup | W2: Sprite | X2: Coco cola | Y2: Column14 | Z2: Thumbsup15 | AA2: Sprite16 | AB2: Fanta | AC2: Coco cola17 | AD2: Column18 | AE2: Column19
A3: 45901 | B3: 6 | C3: =16+23 -> 39 | D3: 0 | F3: 0 | G3: 0 | H3: 0 | J3: 9 | K3: =J3-L3 -> 7.5 | L3: 1.5 | N3: 1.8 | O3: 0 | P3: 1.8 | R3: 2.7 | S3: 5 | T3: 1.4 | V3: =(28*0)+0 -> 0 | W3: =(28*1)+32 -> 60 | X3: =(28*1)+32 -> 60 | Z3: =(24*0)+0 -> 0 | AA3: =(24*0)+0 -> 0 | AB3: 0 | AC3: 0 | AE3: =(12*18)+36 -> 252
A4: 45902 | B4: 8.5 | C4: =15+34 -> 49 | D4: 0 | F4: 0 | G4: 0 | H4: 0 | J4: 9.8 | K4: =J4+L3-L4 -> 8.3 | L4: 3 | N4: 0 | O4: 2 | P4: 2 | R4: 1 | S4: 6 | T4: 2 | V4: =(28*0)+0 -> 0 | W4: =(28*1)+33 -> 61 | X4: =(28*1)+29 -> 57 | Z4: =(24*0)+0 -> 0 | AA4: =(24*0)+0 -> 0 | AB4: =(24*0)+0 -> 0 | AC4: =(24*0)+0 -> 0 | AE4: =(12*18)+25 -> 241
A5: 45903 | B5: 7.5 | C5: =14+34 -> 48 | D5: 0 | F5: 0 | G5: 0 | H5: 0 | J5: 13.3 | K5: =J5+L4-L5 -> 10.4 | L5: 5.9 | N5: 0 | O5: 2 | P5: 1.2 | R5: 0 | S5: 14 | T5: 0.5 | V5: 0 | W5: 0 | X5: 0 | Z5: 0 | AA5: 0 | AB5: 0 | AC5: 0 | AE5: 0
A6: 45904 | B6: 7 | C6: =13+31 -> 44 | D6: 6 | F6: 0 | G6: 0 | H6: 0 | J6: 17.4 | K6: =J6+L5-L6 -> 11.9 | L6: 11.4 | N6: 0 | O6: 6 | P6: 0 | R6: 1.8 | S6: 11 | T6: 2 | V6: =(28*3)+25 -> 109 | W6: =(28*5)+31 -> 171 | X6: =(28*3)+28 -> 112 | Z6: =(24*5)+24 -> 144 | AA6: =(24*5)+24 -> 144 | AB6: =(24*0)+0 -> 0 | AC6: =(24*1)+24 -> 48 | AE6: =(12*16)+24 -> 216
A7: 45905 | B7: 7 | C7: 36 | D7: 6 | F7: 0 | G7: 0 | H7: 0 | J7: 5 | K7: =J7+L6-L7 -> 8.2 | L7: 8.2 | N7: 0 | O7: 0 | P7: 0 | R7: 0 | S7: 24 | T7: 0 | V7: =(28*3)+25 -> 109 | W7: =(28*5)+27 -> 167 | X7: =(28*3)+28 -> 112 | Z7: =(24*5)+14 -> 134 | AA7: =(24*5)+19 -> 139 | AB7: =(24*0)+0 -> 0 | AC7: =(24*1)+21 -> 45 | AE7: =(12*16)+6 -> 198
A8: 45906 | B8: 7 | C8: 35 | D8: 7 | F8: 0 | G8: 0 | H8: 0 | J8: 6.6 | K8: =J8+L7-L8 -> 3.8 | L8: 11 | N8: 1.2 | O8: 3.4 | P8: 0 | R8: 3 | S8: 10 | T8: 1 | V8: =(28*3)+21 -> 105 | W8: =(28*5)+16 -> 156 | X8: =(28*3)+26 -> 110 | Z8: =(24*5)+14 -> 134 | AA8: =(24*5)+18 -> 138 | AB8: =(24*0)+0 -> 0 | AC8: =(24*1)+20 -> 44 | AE8: =(12*12)+32 -> 176
A9: 45907 | B9: 9 | C9: 51 | D9: 0 | F9: 0 | G9: 0 | H9: 0 | J9: 5.9 | K9: =J9+L8-L9 -> 6.9 | L9: 10 | N9: 2.1 | O9: 6.1 | P9: 0 | R9: 2.6 | S9: 29 | T9: 0 | V9: =(28*3)+16 -> 100 | W9: =(28*5)+14 -> 154 | X9: =(28*3)+21 -> 105 | Z9: =(24*5)+13 -> 133 | AA9: =(24*5)+17 -> 137 | AB9: =(24*0)+0 -> 0 | AC9: =(24*1)+16 -> 40 | AE9: =(12*10)+20 -> 140
A10: 45908 | B10: 6 | C10: 29 | D10: 0 | F10: 0 | G10: 0 | H10: 0 | J10: 0 | K10: =J10+L9-L10 -> 4.6 | L10: 5.4 | N10: 0 | O10: 0 | P10: 0 | R10: 3 | S10: 20 | T10: 0 | V10: =(28*3)+9 -> 93 | W10: =(28*5)+11 -> 151 | X10: =(28*3)+19 -> 103 | Z10: =(24*5)+13 -> 133 | AA10: =(24*5)+15 -> 135 | AB10: =(24*0)+0 -> 0 | AC10: =(24*1)+14 -> 38 | AE10: =(12*10)+26 -> 146
A11: 45909 | B11: 5 | C11: 21 | D11: 9 | F11: 0 | G11: 0 | H11: 0 | J11: 9.8 | K11: =J11+L10-L11 -> 3.2 | L11: 12 | N11: 1 | O11: 4 | P11: 0 | R11: 2 | S11: 7 | T11: 0.4 | V11: =(28*2)+37 -> 93 | W11: =(28*4)+38 -> 150 | X11: =(28*3)+19 -> 103 | Z11: =(24*4)+32 -> 128 | AA11: =(24*4)+32 -> 128 | AB11: =(24*0)+0 -> 0 | AC11: =(24*1)+13 -> 37 | AE11: =(12*4)+21 -> 69
A12: 45910 | B12: 6 | C12: 29 | D12: 6 | F12: 0 | G12: 0 | H12: 0 | J12: 6.5 | K12: =J12+L11-L12 -> 4.8 | L12: 13.7 | N12: 1 | O12: 4.4 | P12: 0 | R12: 2 | S12: 9 | T12: 1.3 | V12: 0 | W12: 0 | X12: 0 | Z12: 0 | AA12: 0 | AB12: 0 | AC12: 0 | AE12: 0
A13: 45911 | B13: 5 | C13: 26 | D13: 4 | F13: 1.2 | G13: 3 | H13: 5 | J13: 5.2 | K13: =J13+L12-L13 -> 6.7 | L13: 12.2 | N13: 1.5 | O13: 4 | P13: 0 | R13: 3 | S13: 5 | T13: 4 | V13: 0 | W13: 0 | X13: 0 | Z13: 0 | AA13: 0 | AB13: 0 | AC13: 0 | AE13: 0
A14: 45912 | B14: 5 | C14: 20 | D14: 10 | F14: 1 | G14: 1 | H14: 5 | J14: 0 | K14: =J14+L13-L14 -> 4.2 | L14: 8 | N14: 2.2 | O14: 2.3 | P14: 0.8 | R14: 0 | S14: 4 | T14: 3.3 | V14: 0 | W14: 0 | X14: 0 | Z14: 0 | AA14: 0 | AB14: 0 | AC14: 0 | AE14: 0
A15: 45913 | B15: 6 | C15: 24 | D15: 12 | F15: 2 | G15: 11 | H15: 1 | J15: 7.2 | K15: =J15+L14-L15 -> 5.7 | L15: 9.5 | N15: 0 | O15: 0 | P15: 1.2 | R15: 0 | S15: 9 | T15: 2.4 | V15: 0 | W15: 0 | X15: 0 | Z15: 0 | AA15: 0 | AB15: 0 | AC15: 0 | AE15: 0
A16: 45914 | B16: 7 | C16: 31 | D16: 0 | F16: 2 | G16: 12 | H16: 0 | J16: 0 | K16: =J16+L15-L16 -> 5.6 | L16: 3.9 | N16: 0 | O16: 8.3 | P16: 0.8 | R16: 0 | S16: 12 | T16: 2.3 | V16: 0 | W16: 0 | X16: 0 | Z16: 0 | AA16: 0 | AB16: 0 | AC16: 0 | AE16: 0
A17: 45915 | B17: 5 | C17: 19 | D17: 11 | F17: 0 | G17: 0 | H17: 0 | J17: 6.8 | K17: =J17+L16-L17 -> 4.7 | L17: 6 | N17: 2.1 | O17: 1 | P17: 2.5 | R17: 0 | S17: 7 | T17: 1.7 | V17: =(28*2)+37 -> 93 | W17: =(28*4)+38 -> 150 | X17: =(28*3)+19 -> 103 | Z17: =(24*4)+32 -> 128 | AA17: =(24*4)+32 -> 128 | AB17: =(24*0)+0 -> 0 | AC17: =(24*1)+13 -> 37 | AE17: =(12*4)+21 -> 69
A18: 45916 | B18: 5 | C18: 35 | D18: 0 | F18: 1 | G18: 6 | H18: 0 | J18: 6.3 | K18: =J18+L17-L18 -> 4.8 | L18: 7.5 | N18: 0 | O18: 2.2 | P18: 2 | R18: 1 | S18: 18 | T18: 1 | V18: =(28*2)+17 -> 73 | W18: =(28*4)+27 -> 139 | X18: =(28*3)+12 -> 96 | Z18: =(24*4)+23 -> 119 | AA18: =(24*4)+24 -> 120 | AB18: =(24*0)+0 -> 0 | AC18: =(24*1)+13 -> 37 | AE18: =(12*48)+11 -> 587
A19: 45917 | B19: 5 | C19: 26 | D19: 4 | F19: 1.5 | G19: 0 | H19: 9 | J19: 11.5 | K19: =J19+L18-L19 -> 4.4 | L19: 14.6 | N19: 2.4 | O19: 6.2 | P19: 2.9 | R19: 3 | S19: 10 | T19: 2.5 | V19: 0 | W19: 0 | X19: 0 | Z19: 0 | AA19: 0 | AB19: 0 | AC19: 0 | AE19: 0
A20: 45918 | B20: 5 | C20: 18 | D20: 12 | F20: 0 | G20: 0 | H20: 0 | J20: 0 | K20: =J20+L19-L20 -> 4.3 | L20: 10.3 | N20: 0 | O20: 6.4 | P20: 0.4 | R20: 0 | S20: 14 | T20: 0.8 | V20: 0 | W20: 0 | X20: 0 | Z20: 0 | AA20: 0 | AB20: 0 | AC20: 0 | AE20: 0
A21: 45919 | B21: 4 | C21: 22 | D21: 2 | F21: 0 | G21: 0 | H21: 0 | J21: 0 | K21: =J21+L20-L21 -> 2.5 | L21: 7.8 | N21: 2.2 | O21: 3 | P21: 1.5 | R21: 2.6 | S21: 5 | T21: 2.4 | V21: 0 | W21: 0 | X21: 0 | Z21: 0 | AA21: 0 | AB21: 0 | AC21: 0 | AE21: 0
A22: 45920 | B22: 5 | C22: 23 | D22: 7 | F22: 0 | G22: 0 | H22: 0 | J22: 8 | K22: =J22+L21-L22 -> 3.8 | L22: 12 | N22: 0 | O22: 2.3 | P22: 1.2 | R22: 1.5 | S22: 10 | T22: 2.8 | V22: 0 | W22: 0 | X22: 0 | Z22: 0 | AA22: 0 | AB22: 0 | AC22: 0 | AE22: 0
A23: 45921 | B23: 7 | C23: 49 | D23: 0 | F23: 0 | G23: 0 | H23: 0 | J23: 4.9 | K23: =J23+L22-L23 -> 6.5 | L23: 10.4 | N23: 1.6 | O23: 0 | P23: 2.4 | R23: 0 | S23: 18 | T23: 0.4 | V23: 0 | W23: 0 | X23: 0 | Z23: 0 | AA23: 0 | AB23: 0 | AC23: 0 | AE23: 0
A24: 45922 | B24: 0 | C24: 0 | D24: 0 | F24: 0 | G24: 0 | H24: 0 | J24: 0 | K24: =J24+L23-L24 -> 0 | L24: 10.4 | N24: 0 | O24: 0 | P24: 2.4 | R24: 0 | S24: 0 | T24: 0 | V24: 0 | W24: 0 | X24: 0 | Z24: 0 | AA24: 0 | AB24: 0 | AC24: 0 | AE24: 0
A25: 45923 | B25: 9 | C25: 52 | D25: 2 | F25: 0 | G25: 0 | H25: 0 | J25: 5.2 | K25: =J25+L24-L25 -> 10.3 | L25: 5.3 | N25: 1 | O25: 7 | P25: 2.2 | R25: 2 | S25: 22 | T25: 0 | V25: 0 | W25: 0 | X25: 0 | Z25: 0 | AA25: 0 | AB25: 0 | AC25: 0 | AE25: 0
A26: 45924 | B26: 10 | C26: 46 | D26: 14 | F26: 0 | G26: 0 | H26: 0 | J26: 7.8 | K26: =J26+L25-L26 -> 6.7 | L26: 6.4 | N26: 0 | O26: 6.1 | P26: 0 | R26: 2 | S26: 10 | T26: 1.6 | V26: 0 | W26: 0 | X26: 0 | Z26: 0 | AA26: 0 | AB26: 0 | AC26: 0 | AE26: 0
A27: 45925 | B27: 5 | C27: 21 | D27: 9 | F27: 0 | G27: 0 | H27: 0 | J27: 6.3 | K27: =J27+L26-L27 -> 6.3 | L27: 6.4 | N27: 0 | O27: 1 | P27: 0.6 | R27: 1 | S27: 6 | T27: 2.8 | V27: 0 | W27: 0 | X27: 0 | Z27: 0 | AA27: 0 | AB27: 0 | AC27: 0 | AE27: 0
A28: 45926 | B28: 7 | C28: 43 | D28: 0 | F28: 0 | G28: 0 | H28: 0 | J28: 7.1 | K28: =J28+L27-L28 -> 4.5 | L28: 9 | N28: 1 | O28: 2.2 | P28: 1 | R28: 0 | S28: 13 | T28: 0.8 | V28: 0 | W28: 0 | X28: 0 | Z28: 0 | AA28: 0 | AB28: 0 | AC28: 0 | AE28: 0
A29: 45927 | B29: 8 | C29: 48 | D29: 0 | F29: 0 | G29: 0 | H29: 0 | J29: 6.9 | K29: =J29+L28-L29 -> 8.9 | L29: 7 | N29: 0 | O29: 1 | P29: 1.2 | R29: 2 | S29: 12 | T29: 2.5 | V29: 0 | W29: 0 | X29: 0 | Z29: 0 | AA29: 0 | AB29: 0 | AC29: 0 | AE29: 0
A30: 45928 | B30: 9 | C30: 53 | D30: 1 | F30: 0 | G30: 0 | H30: 0 | J30: 8.4 | K30: =J30+L29-L30 -> 10.1 | L30: 5.3 | N30: 2.5 | O30: 3.2 | P30: 3 | R30: 0 | S30: 15 | T30: 0 | V30: 0 | W30: 0 | X30: 0 | Z30: 0 | AA30: 0 | AB30: 0 | AC30: 0 | AE30: 0
A31: 45929 | B31: 6 | C31: 35 | D31: 1 | F31: 0 | G31: 0 | H31: 0 | J31: 6.3 | K31: =J31+L30-L31 -> 5.3 | L31: 6.3 | N31: 0 | O31: 10 | P31: 0 | R31: 1.6 | S31: 14 | T31: 1.3 | V31: =(28*1)+32 -> 60 | W31: =(28*3)+36 -> 120 | X31: =(28*3)+25 -> 109 | Z31: =(24*3)+30 -> 102 | AA31: =(24*4)+16 -> 112 | AB31: =(24*0)+0 -> 0 | AC31: =(24*1)+7 -> 31 | AE31: =(12*32)+21 -> 405
A32: 45930 | B32: 11 | C32: 47 | D32: 0 | F32: 0 | G32: 0 | H32: 0 | J32: 11.1 | K32: =J32+L31-L32 -> 9.1 | L32: 8.3 | N32: 0 | O32: 0.3 | P32: 0 | R32: 1 | S32: 26 | T32: 0 | V32: 0 | W32: 0 | X32: 0 | Z32: 0 | AA32: 0 | AB32: 0 | AC32: 0 | AE32: 0
A33: Total | B33: =SUM(B3:B32) -> 193 | C33: =SUM(C3:C32) -> 1019 | D33: =SUM(D3:D32) -> 123 | F33: =SUM(F3:F32) -> 8.7 | G33: =SUM(G3:G32) -> 33 | H33: =SUM(H3:H32) -> 20 | J33: =SUM(J3:J32) -> 192.3 | K33: =SUM(K3:K32) -> 184 | N33: =SUM(N3:N32) -> 23.6 | O33: =SUM(O3:O32) -> 94.4 | R33: =SUM(R3:R32) -> 38.8 | S33: =SUM(S3:S32) -> 365
